
Not Found: /favicon.ico
Not Found: /pomo/library/timerWorker.js
Not Found: /pomo/library/timerWorker.js
Not Found: /pomo/library/pomo/timerWorker.js
Not Found: /favicon.ico
Not Found: /pomo/library/pomo/js/timerWorker.js
Not Found: /favicon.ico
Not Found: /pomo/library/js/timerWorker.js
Not Found: /favicon.ico
Exception while resolving variable 'streak' in template 'pomo/start.html'.
Traceback (most recent call last):
  File "/home/timoh/projects/master-o-meter/.venv/lib/python3.9/site-packages/django/template/base.py", line 880, in _resolve_lookup
    current = current[bit]
  File "/home/timoh/projects/master-o-meter/.venv/lib/python3.9/site-packages/django/template/context.py", line 83, in __getitem__
    raise KeyError(key)
KeyError: 'streak'

During handling of the above exception, another exception occurred:

Traceback (most recent call last):
  File "/home/timoh/projects/master-o-meter/.venv/lib/python3.9/site-packages/django/template/base.py", line 886, in _resolve_lookup
    if isinstance(current, BaseContext) and getattr(
AttributeError: type object 'RequestContext' has no attribute 'streak'

During handling of the above exception, another exception occurred:

Traceback (most recent call last):
  File "/home/timoh/projects/master-o-meter/.venv/lib/python3.9/site-packages/django/template/base.py", line 896, in _resolve_lookup
    current = current[int(bit)]
ValueError: invalid literal for int() with base 10: 'streak'

During handling of the above exception, another exception occurred:

Traceback (most recent call last):
  File "/home/timoh/projects/master-o-meter/.venv/lib/python3.9/site-packages/django/template/base.py", line 903, in _resolve_lookup
    raise VariableDoesNotExist(
django.template.base.VariableDoesNotExist: Failed lookup for key [streak] in [{'True': True, 'False': False, 'None': None}, {'csrf_token': <SimpleLazyObject: <function csrf.<locals>._get_val at 0xece0ba00>>, 'request': <WSGIRequest: GET '/pomo/start/'>, 'user': <SimpleLazyObject: <User: timoh>>, 'perms': PermWrapper(<SimpleLazyObject: <User: timoh>>), 'messages': <FallbackStorage: request=<WSGIRequest: GET '/pomo/start/'>>, 'DEFAULT_MESSAGE_LEVELS': {'DEBUG': 10, 'INFO': 20, 'SUCCESS': 25, 'WARNING': 30, 'ERROR': 40}}, {}, {}]
Exception while resolving variable 'total_pomodoros_today' in template 'pomo/start.html'.
Traceback (most recent call last):
  File "/home/timoh/projects/master-o-meter/.venv/lib/python3.9/site-packages/django/template/base.py", line 880, in _resolve_lookup
    current = current[bit]
  File "/home/timoh/projects/master-o-meter/.venv/lib/python3.9/site-packages/django/template/context.py", line 83, in __getitem__
    raise KeyError(key)
KeyError: 'total_pomodoros_today'

During handling of the above exception, another exception occurred:

Traceback (most recent call last):
  File "/home/timoh/projects/master-o-meter/.venv/lib/python3.9/site-packages/django/template/base.py", line 886, in _resolve_lookup
    if isinstance(current, BaseContext) and getattr(
AttributeError: type object 'RequestContext' has no attribute 'total_pomodoros_today'

During handling of the above exception, another exception occurred:

Traceback (most recent call last):
  File "/home/timoh/projects/master-o-meter/.venv/lib/python3.9/site-packages/django/template/base.py", line 896, in _resolve_lookup
    current = current[int(bit)]
ValueError: invalid literal for int() with base 10: 'total_pomodoros_today'

During handling of the above exception, another exception occurred:

Traceback (most recent call last):
  File "/home/timoh/projects/master-o-meter/.venv/lib/python3.9/site-packages/django/template/base.py", line 903, in _resolve_lookup
    raise VariableDoesNotExist(
django.template.base.VariableDoesNotExist: Failed lookup for key [total_pomodoros_today] in [{'True': True, 'False': False, 'None': None}, {'csrf_token': <SimpleLazyObject: <function csrf.<locals>._get_val at 0xece0ba00>>, 'request': <WSGIRequest: GET '/pomo/start/'>, 'user': <SimpleLazyObject: <User: timoh>>, 'perms': PermWrapper(<SimpleLazyObject: <User: timoh>>), 'messages': <FallbackStorage: request=<WSGIRequest: GET '/pomo/start/'>>, 'DEFAULT_MESSAGE_LEVELS': {'DEBUG': 10, 'INFO': 20, 'SUCCESS': 25, 'WARNING': 30, 'ERROR': 40}}, {}, {}]
Not Found: /favicon.ico
Not Found: /favicon.ico
Not Found: /favicon.ico
Exception while resolving variable 'player_state_json' in template 'pomo/map.html'.
Traceback (most recent call last):
  File "/home/timoh/projects/master-o-meter/.venv/lib/python3.9/site-packages/django/template/base.py", line 880, in _resolve_lookup
    current = current[bit]
  File "/home/timoh/projects/master-o-meter/.venv/lib/python3.9/site-packages/django/template/context.py", line 83, in __getitem__
    raise KeyError(key)
KeyError: 'player_state_json'

During handling of the above exception, another exception occurred:

Traceback (most recent call last):
  File "/home/timoh/projects/master-o-meter/.venv/lib/python3.9/site-packages/django/template/base.py", line 886, in _resolve_lookup
    if isinstance(current, BaseContext) and getattr(
AttributeError: type object 'RequestContext' has no attribute 'player_state_json'

During handling of the above exception, another exception occurred:

Traceback (most recent call last):
  File "/home/timoh/projects/master-o-meter/.venv/lib/python3.9/site-packages/django/template/base.py", line 896, in _resolve_lookup
    current = current[int(bit)]
ValueError: invalid literal for int() with base 10: 'player_state_json'

During handling of the above exception, another exception occurred:

Traceback (most recent call last):
  File "/home/timoh/projects/master-o-meter/.venv/lib/python3.9/site-packages/django/template/base.py", line 903, in _resolve_lookup
    raise VariableDoesNotExist(
django.template.base.VariableDoesNotExist: Failed lookup for key [player_state_json] in [{'True': True, 'False': False, 'None': None}, {'csrf_token': <SimpleLazyObject: 'S1eJxkGxOwdZplbHxwzlWprJmvCF6YhIg5PQnDOrrFJQsuYgstjg0l4J7xZBySdD'>, 'request': <WSGIRequest: GET '/pomo/map/'>, 'user': <SimpleLazyObject: <User: timoh>>, 'perms': PermWrapper(<SimpleLazyObject: <User: timoh>>), 'messages': <FallbackStorage: request=<WSGIRequest: GET '/pomo/map/'>>, 'DEFAULT_MESSAGE_LEVELS': {'DEBUG': 10, 'INFO': 20, 'SUCCESS': 25, 'WARNING': 30, 'ERROR': 40}}, {}, {'total_pomos_alltime': 195, 'total_pomodoros_today': 6, 'streak': 16, 'highest_streak': 16, 'is_developer': False, 'username': 'timoh'}]
Exception while resolving variable 'location_states_json' in template 'pomo/map.html'.
Traceback (most recent call last):
  File "/home/timoh/projects/master-o-meter/.venv/lib/python3.9/site-packages/django/template/base.py", line 880, in _resolve_lookup
    current = current[bit]
  File "/home/timoh/projects/master-o-meter/.venv/lib/python3.9/site-packages/django/template/context.py", line 83, in __getitem__
    raise KeyError(key)
KeyError: 'location_states_json'

During handling of the above exception, another exception occurred:

Traceback (most recent call last):
  File "/home/timoh/projects/master-o-meter/.venv/lib/python3.9/site-packages/django/template/base.py", line 886, in _resolve_lookup
    if isinstance(current, BaseContext) and getattr(
AttributeError: type object 'RequestContext' has no attribute 'location_states_json'

During handling of the above exception, another exception occurred:

Traceback (most recent call last):
  File "/home/timoh/projects/master-o-meter/.venv/lib/python3.9/site-packages/django/template/base.py", line 896, in _resolve_lookup
    current = current[int(bit)]
ValueError: invalid literal for int() with base 10: 'location_states_json'

During handling of the above exception, another exception occurred:

Traceback (most recent call last):
  File "/home/timoh/projects/master-o-meter/.venv/lib/python3.9/site-packages/django/template/base.py", line 903, in _resolve_lookup
    raise VariableDoesNotExist(
django.template.base.VariableDoesNotExist: Failed lookup for key [location_states_json] in [{'True': True, 'False': False, 'None': None}, {'csrf_token': <SimpleLazyObject: 'S1eJxkGxOwdZplbHxwzlWprJmvCF6YhIg5PQnDOrrFJQsuYgstjg0l4J7xZBySdD'>, 'request': <WSGIRequest: GET '/pomo/map/'>, 'user': <SimpleLazyObject: <User: timoh>>, 'perms': PermWrapper(<SimpleLazyObject: <User: timoh>>), 'messages': <FallbackStorage: request=<WSGIRequest: GET '/pomo/map/'>>, 'DEFAULT_MESSAGE_LEVELS': {'DEBUG': 10, 'INFO': 20, 'SUCCESS': 25, 'WARNING': 30, 'ERROR': 40}}, {}, {'total_pomos_alltime': 195, 'total_pomodoros_today': 6, 'streak': 16, 'highest_streak': 16, 'is_developer': False, 'username': 'timoh'}]
Not Found: /favicon.ico
Not Found: /favicon.ico
Not Found: /favicon.ico
Not Found: /favicon.ico
Invalid HTTP_HOST header: '[2001:4dd1:4f06:0:8db3:764:fd94:f474]'. You may need to add '[2001:4dd1:4f06:0:8db3:764:fd94:f474]' to ALLOWED_HOSTS.
Traceback (most recent call last):
  File "/home/timoh/projects/master-o-meter/.venv/lib/python3.9/site-packages/django/core/handlers/exception.py", line 55, in inner
    response = get_response(request)
  File "/home/timoh/projects/master-o-meter/.venv/lib/python3.9/site-packages/django/utils/deprecation.py", line 133, in __call__
    response = self.process_request(request)
  File "/home/timoh/projects/master-o-meter/.venv/lib/python3.9/site-packages/django/middleware/common.py", line 48, in process_request
    host = request.get_host()
  File "/home/timoh/projects/master-o-meter/.venv/lib/python3.9/site-packages/django/http/request.py", line 150, in get_host
    raise DisallowedHost(msg)
django.core.exceptions.DisallowedHost: Invalid HTTP_HOST header: '[2001:4dd1:4f06:0:8db3:764:fd94:f474]'. You may need to add '[2001:4dd1:4f06:0:8db3:764:fd94:f474]' to ALLOWED_HOSTS.
Bad Request: /
Not Found: /favicon.ico
Not Found: /favicon.ico
Not Found: /favicon.ico
Not Found: /favicon.ico
Not Found: /favicon.ico
CREATE TABLE "pomo_achievementcondition" ("id" integer NOT NULL PRIMARY KEY AUTOINCREMENT); (params None)
CREATE TABLE "pomo_quest" ("id" integer NOT NULL PRIMARY KEY AUTOINCREMENT, "name" varchar(255) NOT NULL, "description" text NOT NULL); (params None)
CREATE TABLE "pomo_queststep" ("id" integer NOT NULL PRIMARY KEY AUTOINCREMENT, "step_number" integer NOT NULL, "pre_timer_text" text NULL, "post_timer_text" text NULL, "timer_duration" integer NOT NULL, "quest_id" bigint NOT NULL REFERENCES "pomo_quest" ("id") DEFERRABLE INITIALLY DEFERRED); (params None)
CREATE TABLE "pomo_playerquestprogress" ("id" integer NOT NULL PRIMARY KEY AUTOINCREMENT, "current_step" integer NOT NULL, "is_completed" BLOB NOT NULL, "player_id" integer NOT NULL REFERENCES "auth_user" ("id") DEFERRABLE INITIALLY DEFERRED, "quest_id" bigint NOT NULL REFERENCES "pomo_quest" ("id") DEFERRABLE INITIALLY DEFERRED); (params None)
CREATE INDEX "pomo_queststep_quest_id_601c3b3c" ON "pomo_queststep" ("quest_id"); (params ())
CREATE INDEX "pomo_playerquestprogress_player_id_a72da212" ON "pomo_playerquestprogress" ("player_id"); (params ())
CREATE INDEX "pomo_playerquestprogress_quest_id_8d021181" ON "pomo_playerquestprogress" ("quest_id"); (params ())
Not Found: /pomo/event/9/static/pomo/audio/alarm1.mp3
Not Found: /favicon.ico
Not Found: /favicon.ico
Internal Server Error: /pomo/quest/1/
Traceback (most recent call last):
  File "/home/timoh/projects/master-o-meter/.venv/lib/python3.9/site-packages/django/core/handlers/exception.py", line 55, in inner
    response = get_response(request)
  File "/home/timoh/projects/master-o-meter/.venv/lib/python3.9/site-packages/django/core/handlers/base.py", line 197, in _get_response
    response = wrapped_callback(request, *callback_args, **callback_kwargs)
  File "/home/timoh/projects/master-o-meter/.venv/lib/python3.9/site-packages/django/contrib/auth/decorators.py", line 23, in _wrapper_view
    return view_func(request, *args, **kwargs)
  File "/home/timoh/projects/master-o-meter/webapp/pomo/views.py", line 638, in quest_detail
    return redirect('hub')
  File "/home/timoh/projects/master-o-meter/.venv/lib/python3.9/site-packages/django/shortcuts.py", line 48, in redirect
    return redirect_class(resolve_url(to, *args, **kwargs))
  File "/home/timoh/projects/master-o-meter/.venv/lib/python3.9/site-packages/django/shortcuts.py", line 145, in resolve_url
    return reverse(to, args=args, kwargs=kwargs)
  File "/home/timoh/projects/master-o-meter/.venv/lib/python3.9/site-packages/django/urls/base.py", line 88, in reverse
    return resolver._reverse_with_prefix(view, prefix, *args, **kwargs)
  File "/home/timoh/projects/master-o-meter/.venv/lib/python3.9/site-packages/django/urls/resolvers.py", line 828, in _reverse_with_prefix
    raise NoReverseMatch(msg)
django.urls.exceptions.NoReverseMatch: Reverse for 'hub' not found. 'hub' is not a valid view function or pattern name.
Internal Server Error: /pomo/quest/1/
Traceback (most recent call last):
  File "/home/timoh/projects/master-o-meter/.venv/lib/python3.9/site-packages/django/core/handlers/exception.py", line 55, in inner
    response = get_response(request)
  File "/home/timoh/projects/master-o-meter/.venv/lib/python3.9/site-packages/django/core/handlers/base.py", line 197, in _get_response
    response = wrapped_callback(request, *callback_args, **callback_kwargs)
  File "/home/timoh/projects/master-o-meter/.venv/lib/python3.9/site-packages/django/contrib/auth/decorators.py", line 23, in _wrapper_view
    return view_func(request, *args, **kwargs)
  File "/home/timoh/projects/master-o-meter/webapp/pomo/views.py", line 638, in quest_detail
    return redirect('hub')
  File "/home/timoh/projects/master-o-meter/.venv/lib/python3.9/site-packages/django/shortcuts.py", line 48, in redirect
    return redirect_class(resolve_url(to, *args, **kwargs))
  File "/home/timoh/projects/master-o-meter/.venv/lib/python3.9/site-packages/django/shortcuts.py", line 145, in resolve_url
    return reverse(to, args=args, kwargs=kwargs)
  File "/home/timoh/projects/master-o-meter/.venv/lib/python3.9/site-packages/django/urls/base.py", line 88, in reverse
    return resolver._reverse_with_prefix(view, prefix, *args, **kwargs)
  File "/home/timoh/projects/master-o-meter/.venv/lib/python3.9/site-packages/django/urls/resolvers.py", line 828, in _reverse_with_prefix
    raise NoReverseMatch(msg)
django.urls.exceptions.NoReverseMatch: Reverse for 'hub' not found. 'hub' is not a valid view function or pattern name.
Internal Server Error: /admin/pomo/playerquestprogress/add/
Traceback (most recent call last):
  File "/home/timoh/projects/master-o-meter/.venv/lib/python3.9/site-packages/django/core/handlers/exception.py", line 55, in inner
    response = get_response(request)
  File "/home/timoh/projects/master-o-meter/.venv/lib/python3.9/site-packages/django/core/handlers/base.py", line 197, in _get_response
    response = wrapped_callback(request, *callback_args, **callback_kwargs)
  File "/home/timoh/projects/master-o-meter/.venv/lib/python3.9/site-packages/django/contrib/admin/options.py", line 688, in wrapper
    return self.admin_site.admin_view(view)(*args, **kwargs)
  File "/home/timoh/projects/master-o-meter/.venv/lib/python3.9/site-packages/django/utils/decorators.py", line 134, in _wrapper_view
    response = view_func(request, *args, **kwargs)
  File "/home/timoh/projects/master-o-meter/.venv/lib/python3.9/site-packages/django/views/decorators/cache.py", line 62, in _wrapper_view_func
    response = view_func(request, *args, **kwargs)
  File "/home/timoh/projects/master-o-meter/.venv/lib/python3.9/site-packages/django/contrib/admin/sites.py", line 242, in inner
    return view(request, *args, **kwargs)
  File "/home/timoh/projects/master-o-meter/.venv/lib/python3.9/site-packages/django/contrib/admin/options.py", line 1886, in add_view
    return self.changeform_view(request, None, form_url, extra_context)
  File "/home/timoh/projects/master-o-meter/.venv/lib/python3.9/site-packages/django/utils/decorators.py", line 46, in _wrapper
    return bound_method(*args, **kwargs)
  File "/home/timoh/projects/master-o-meter/.venv/lib/python3.9/site-packages/django/utils/decorators.py", line 134, in _wrapper_view
    response = view_func(request, *args, **kwargs)
  File "/home/timoh/projects/master-o-meter/.venv/lib/python3.9/site-packages/django/contrib/admin/options.py", line 1747, in changeform_view
    return self._changeform_view(request, object_id, form_url, extra_context)
  File "/home/timoh/projects/master-o-meter/.venv/lib/python3.9/site-packages/django/contrib/admin/options.py", line 1798, in _changeform_view
    self.save_model(request, new_object, form, not add)
  File "/home/timoh/projects/master-o-meter/.venv/lib/python3.9/site-packages/django/contrib/admin/options.py", line 1227, in save_model
    obj.save()
  File "/home/timoh/projects/master-o-meter/.venv/lib/python3.9/site-packages/django/db/models/base.py", line 814, in save
    self.save_base(
  File "/home/timoh/projects/master-o-meter/.venv/lib/python3.9/site-packages/django/db/models/base.py", line 877, in save_base
    updated = self._save_table(
  File "/home/timoh/projects/master-o-meter/.venv/lib/python3.9/site-packages/django/db/models/base.py", line 1020, in _save_table
    results = self._do_insert(
  File "/home/timoh/projects/master-o-meter/.venv/lib/python3.9/site-packages/django/db/models/base.py", line 1061, in _do_insert
    return manager._insert(
  File "/home/timoh/projects/master-o-meter/.venv/lib/python3.9/site-packages/django/db/models/manager.py", line 87, in manager_method
    return getattr(self.get_queryset(), name)(*args, **kwargs)
  File "/home/timoh/projects/master-o-meter/.venv/lib/python3.9/site-packages/django/db/models/query.py", line 1805, in _insert
    return query.get_compiler(using=using).execute_sql(returning_fields)
  File "/home/timoh/projects/master-o-meter/.venv/lib/python3.9/site-packages/django/db/models/sql/compiler.py", line 1821, in execute_sql
    for sql, params in self.as_sql():
  File "/home/timoh/projects/master-o-meter/.venv/lib/python3.9/site-packages/django/db/models/sql/compiler.py", line 1745, in as_sql
    value_rows = [
  File "/home/timoh/projects/master-o-meter/.venv/lib/python3.9/site-packages/django/db/models/sql/compiler.py", line 1746, in <listcomp>
    [
  File "/home/timoh/projects/master-o-meter/.venv/lib/python3.9/site-packages/django/db/models/sql/compiler.py", line 1747, in <listcomp>
    self.prepare_value(field, self.pre_save_val(field, obj))
  File "/home/timoh/projects/master-o-meter/.venv/lib/python3.9/site-packages/django/db/models/sql/compiler.py", line 1686, in prepare_value
    return field.get_db_prep_save(value, connection=self.connection)
  File "/home/timoh/projects/master-o-meter/.venv/lib/python3.9/site-packages/django/db/models/fields/__init__.py", line 954, in get_db_prep_save
    return self.get_db_prep_value(value, connection=connection, prepared=False)
  File "/home/timoh/projects/master-o-meter/.venv/lib/python3.9/site-packages/django/db/models/fields/__init__.py", line 2637, in get_db_prep_value
    return connection.Database.Binary(value)
TypeError: memoryview: a bytes-like object is required, not 'bool'
Internal Server Error: /admin/pomo/playerquestprogress/add/
Traceback (most recent call last):
  File "/home/timoh/projects/master-o-meter/.venv/lib/python3.9/site-packages/django/core/handlers/exception.py", line 55, in inner
    response = get_response(request)
  File "/home/timoh/projects/master-o-meter/.venv/lib/python3.9/site-packages/django/core/handlers/base.py", line 197, in _get_response
    response = wrapped_callback(request, *callback_args, **callback_kwargs)
  File "/home/timoh/projects/master-o-meter/.venv/lib/python3.9/site-packages/django/contrib/admin/options.py", line 688, in wrapper
    return self.admin_site.admin_view(view)(*args, **kwargs)
  File "/home/timoh/projects/master-o-meter/.venv/lib/python3.9/site-packages/django/utils/decorators.py", line 134, in _wrapper_view
    response = view_func(request, *args, **kwargs)
  File "/home/timoh/projects/master-o-meter/.venv/lib/python3.9/site-packages/django/views/decorators/cache.py", line 62, in _wrapper_view_func
    response = view_func(request, *args, **kwargs)
  File "/home/timoh/projects/master-o-meter/.venv/lib/python3.9/site-packages/django/contrib/admin/sites.py", line 242, in inner
    return view(request, *args, **kwargs)
  File "/home/timoh/projects/master-o-meter/.venv/lib/python3.9/site-packages/django/contrib/admin/options.py", line 1886, in add_view
    return self.changeform_view(request, None, form_url, extra_context)
  File "/home/timoh/projects/master-o-meter/.venv/lib/python3.9/site-packages/django/utils/decorators.py", line 46, in _wrapper
    return bound_method(*args, **kwargs)
  File "/home/timoh/projects/master-o-meter/.venv/lib/python3.9/site-packages/django/utils/decorators.py", line 134, in _wrapper_view
    response = view_func(request, *args, **kwargs)
  File "/home/timoh/projects/master-o-meter/.venv/lib/python3.9/site-packages/django/contrib/admin/options.py", line 1747, in changeform_view
    return self._changeform_view(request, object_id, form_url, extra_context)
  File "/home/timoh/projects/master-o-meter/.venv/lib/python3.9/site-packages/django/contrib/admin/options.py", line 1798, in _changeform_view
    self.save_model(request, new_object, form, not add)
  File "/home/timoh/projects/master-o-meter/.venv/lib/python3.9/site-packages/django/contrib/admin/options.py", line 1227, in save_model
    obj.save()
  File "/home/timoh/projects/master-o-meter/.venv/lib/python3.9/site-packages/django/db/models/base.py", line 814, in save
    self.save_base(
  File "/home/timoh/projects/master-o-meter/.venv/lib/python3.9/site-packages/django/db/models/base.py", line 877, in save_base
    updated = self._save_table(
  File "/home/timoh/projects/master-o-meter/.venv/lib/python3.9/site-packages/django/db/models/base.py", line 1020, in _save_table
    results = self._do_insert(
  File "/home/timoh/projects/master-o-meter/.venv/lib/python3.9/site-packages/django/db/models/base.py", line 1061, in _do_insert
    return manager._insert(
  File "/home/timoh/projects/master-o-meter/.venv/lib/python3.9/site-packages/django/db/models/manager.py", line 87, in manager_method
    return getattr(self.get_queryset(), name)(*args, **kwargs)
  File "/home/timoh/projects/master-o-meter/.venv/lib/python3.9/site-packages/django/db/models/query.py", line 1805, in _insert
    return query.get_compiler(using=using).execute_sql(returning_fields)
  File "/home/timoh/projects/master-o-meter/.venv/lib/python3.9/site-packages/django/db/models/sql/compiler.py", line 1821, in execute_sql
    for sql, params in self.as_sql():
  File "/home/timoh/projects/master-o-meter/.venv/lib/python3.9/site-packages/django/db/models/sql/compiler.py", line 1745, in as_sql
    value_rows = [
  File "/home/timoh/projects/master-o-meter/.venv/lib/python3.9/site-packages/django/db/models/sql/compiler.py", line 1746, in <listcomp>
    [
  File "/home/timoh/projects/master-o-meter/.venv/lib/python3.9/site-packages/django/db/models/sql/compiler.py", line 1747, in <listcomp>
    self.prepare_value(field, self.pre_save_val(field, obj))
  File "/home/timoh/projects/master-o-meter/.venv/lib/python3.9/site-packages/django/db/models/sql/compiler.py", line 1686, in prepare_value
    return field.get_db_prep_save(value, connection=self.connection)
  File "/home/timoh/projects/master-o-meter/.venv/lib/python3.9/site-packages/django/db/models/fields/__init__.py", line 954, in get_db_prep_save
    return self.get_db_prep_value(value, connection=connection, prepared=False)
  File "/home/timoh/projects/master-o-meter/.venv/lib/python3.9/site-packages/django/db/models/fields/__init__.py", line 2637, in get_db_prep_value
    return connection.Database.Binary(value)
TypeError: memoryview: a bytes-like object is required, not 'bool'
CREATE TABLE "new__pomo_playerquestprogress" ("id" integer NOT NULL PRIMARY KEY AUTOINCREMENT, "current_step" integer NOT NULL, "player_id" integer NOT NULL REFERENCES "auth_user" ("id") DEFERRABLE INITIALLY DEFERRED, "quest_id" bigint NOT NULL REFERENCES "pomo_quest" ("id") DEFERRABLE INITIALLY DEFERRED, "is_completed" bool NOT NULL); (params None)
INSERT INTO "new__pomo_playerquestprogress" ("id", "current_step", "player_id", "quest_id", "is_completed") SELECT "id", "current_step", "player_id", "quest_id", "is_completed" FROM "pomo_playerquestprogress"; (params ())
DROP TABLE "pomo_playerquestprogress"; (params ())
ALTER TABLE "new__pomo_playerquestprogress" RENAME TO "pomo_playerquestprogress"; (params ())
CREATE INDEX "pomo_playerquestprogress_player_id_a72da212" ON "pomo_playerquestprogress" ("player_id"); (params ())
CREATE INDEX "pomo_playerquestprogress_quest_id_8d021181" ON "pomo_playerquestprogress" ("quest_id"); (params ())
Not Found: /favicon.ico
Exception while resolving variable 'size' in template 'pomo/hub.html'.
Traceback (most recent call last):
  File "/home/timoh/projects/master-o-meter/.venv/lib/python3.9/site-packages/django/template/base.py", line 880, in _resolve_lookup
    current = current[bit]
TypeError: 'Quest' object is not subscriptable

During handling of the above exception, another exception occurred:

Traceback (most recent call last):
  File "/home/timoh/projects/master-o-meter/.venv/lib/python3.9/site-packages/django/template/base.py", line 890, in _resolve_lookup
    current = getattr(current, bit)
AttributeError: 'Quest' object has no attribute 'size'

During handling of the above exception, another exception occurred:

Traceback (most recent call last):
  File "/home/timoh/projects/master-o-meter/.venv/lib/python3.9/site-packages/django/template/base.py", line 896, in _resolve_lookup
    current = current[int(bit)]
ValueError: invalid literal for int() with base 10: 'size'

During handling of the above exception, another exception occurred:

Traceback (most recent call last):
  File "/home/timoh/projects/master-o-meter/.venv/lib/python3.9/site-packages/django/template/base.py", line 903, in _resolve_lookup
    raise VariableDoesNotExist(
django.template.base.VariableDoesNotExist: Failed lookup for key [size] in <Quest: Welcome Ceremony>
Internal Server Error: /pomo/quest/1/
Traceback (most recent call last):
  File "/home/timoh/projects/master-o-meter/.venv/lib/python3.9/site-packages/django/core/handlers/exception.py", line 55, in inner
    response = get_response(request)
  File "/home/timoh/projects/master-o-meter/.venv/lib/python3.9/site-packages/django/core/handlers/base.py", line 197, in _get_response
    response = wrapped_callback(request, *callback_args, **callback_kwargs)
  File "/home/timoh/projects/master-o-meter/.venv/lib/python3.9/site-packages/django/contrib/auth/decorators.py", line 23, in _wrapper_view
    return view_func(request, *args, **kwargs)
  File "/home/timoh/projects/master-o-meter/webapp/pomo/views.py", line 647, in quest_detail
    'total_steps': quest.size,
AttributeError: 'Quest' object has no attribute 'size'
Internal Server Error: /pomo/quest/1/
Traceback (most recent call last):
  File "/home/timoh/projects/master-o-meter/.venv/lib/python3.9/site-packages/django/template/base.py", line 505, in parse
    compile_func = self.tags[command]
KeyError: 'bootstrap_css'

During handling of the above exception, another exception occurred:

Traceback (most recent call last):
  File "/home/timoh/projects/master-o-meter/.venv/lib/python3.9/site-packages/django/core/handlers/exception.py", line 55, in inner
    response = get_response(request)
  File "/home/timoh/projects/master-o-meter/.venv/lib/python3.9/site-packages/django/core/handlers/base.py", line 197, in _get_response
    response = wrapped_callback(request, *callback_args, **callback_kwargs)
  File "/home/timoh/projects/master-o-meter/.venv/lib/python3.9/site-packages/django/contrib/auth/decorators.py", line 23, in _wrapper_view
    return view_func(request, *args, **kwargs)
  File "/home/timoh/projects/master-o-meter/webapp/pomo/views.py", line 650, in quest_detail
    return render(request, 'pomo/quests/base_quest.html', context)
  File "/home/timoh/projects/master-o-meter/.venv/lib/python3.9/site-packages/django/shortcuts.py", line 24, in render
    content = loader.render_to_string(template_name, context, request, using=using)
  File "/home/timoh/projects/master-o-meter/.venv/lib/python3.9/site-packages/django/template/loader.py", line 61, in render_to_string
    template = get_template(template_name, using=using)
  File "/home/timoh/projects/master-o-meter/.venv/lib/python3.9/site-packages/django/template/loader.py", line 15, in get_template
    return engine.get_template(template_name)
  File "/home/timoh/projects/master-o-meter/.venv/lib/python3.9/site-packages/django/template/backends/django.py", line 33, in get_template
    return Template(self.engine.get_template(template_name), self)
  File "/home/timoh/projects/master-o-meter/.venv/lib/python3.9/site-packages/django/template/engine.py", line 175, in get_template
    template, origin = self.find_template(template_name)
  File "/home/timoh/projects/master-o-meter/.venv/lib/python3.9/site-packages/django/template/engine.py", line 157, in find_template
    template = loader.get_template(name, skip=skip)
  File "/home/timoh/projects/master-o-meter/.venv/lib/python3.9/site-packages/django/template/loaders/cached.py", line 57, in get_template
    template = super().get_template(template_name, skip)
  File "/home/timoh/projects/master-o-meter/.venv/lib/python3.9/site-packages/django/template/loaders/base.py", line 28, in get_template
    return Template(
  File "/home/timoh/projects/master-o-meter/.venv/lib/python3.9/site-packages/django/template/base.py", line 154, in __init__
    self.nodelist = self.compile_nodelist()
  File "/home/timoh/projects/master-o-meter/.venv/lib/python3.9/site-packages/django/template/base.py", line 200, in compile_nodelist
    return parser.parse()
  File "/home/timoh/projects/master-o-meter/.venv/lib/python3.9/site-packages/django/template/base.py", line 507, in parse
    self.invalid_block_tag(token, command, parse_until)
  File "/home/timoh/projects/master-o-meter/.venv/lib/python3.9/site-packages/django/template/base.py", line 568, in invalid_block_tag
    raise self.error(
django.template.exceptions.TemplateSyntaxError: Invalid block tag on line 8: 'bootstrap_css'. Did you forget to register or load this tag?
Exception while resolving variable 'streak' in template 'pomo/quests/base_quest.html'.
Traceback (most recent call last):
  File "/home/timoh/projects/master-o-meter/.venv/lib/python3.9/site-packages/django/template/base.py", line 880, in _resolve_lookup
    current = current[bit]
  File "/home/timoh/projects/master-o-meter/.venv/lib/python3.9/site-packages/django/template/context.py", line 83, in __getitem__
    raise KeyError(key)
KeyError: 'streak'

During handling of the above exception, another exception occurred:

Traceback (most recent call last):
  File "/home/timoh/projects/master-o-meter/.venv/lib/python3.9/site-packages/django/template/base.py", line 886, in _resolve_lookup
    if isinstance(current, BaseContext) and getattr(
AttributeError: type object 'RequestContext' has no attribute 'streak'

During handling of the above exception, another exception occurred:

Traceback (most recent call last):
  File "/home/timoh/projects/master-o-meter/.venv/lib/python3.9/site-packages/django/template/base.py", line 896, in _resolve_lookup
    current = current[int(bit)]
ValueError: invalid literal for int() with base 10: 'streak'

During handling of the above exception, another exception occurred:

Traceback (most recent call last):
  File "/home/timoh/projects/master-o-meter/.venv/lib/python3.9/site-packages/django/template/base.py", line 903, in _resolve_lookup
    raise VariableDoesNotExist(
django.template.base.VariableDoesNotExist: Failed lookup for key [streak] in [{'True': True, 'False': False, 'None': None}, {'csrf_token': <SimpleLazyObject: <function csrf.<locals>._get_val at 0xecd23580>>, 'request': <WSGIRequest: GET '/pomo/quest/1/'>, 'user': <SimpleLazyObject: <User: timoh>>, 'perms': PermWrapper(<SimpleLazyObject: <User: timoh>>), 'messages': <FallbackStorage: request=<WSGIRequest: GET '/pomo/quest/1/'>>, 'DEFAULT_MESSAGE_LEVELS': {'DEBUG': 10, 'INFO': 20, 'SUCCESS': 25, 'WARNING': 30, 'ERROR': 40}}, {}, {'quest_name': 'Welcome Ceremony', 'current_step': 0, 'total_steps': 3, 'steps': <QuerySet [<QuestStep: Welcome Ceremony - Step 1>, <QuestStep: Welcome Ceremony - Step 2>, <QuestStep: Welcome Ceremony - Step 3>]>}, {}]
Exception while resolving variable 'total_pomodoros_today' in template 'pomo/quests/base_quest.html'.
Traceback (most recent call last):
  File "/home/timoh/projects/master-o-meter/.venv/lib/python3.9/site-packages/django/template/base.py", line 880, in _resolve_lookup
    current = current[bit]
  File "/home/timoh/projects/master-o-meter/.venv/lib/python3.9/site-packages/django/template/context.py", line 83, in __getitem__
    raise KeyError(key)
KeyError: 'total_pomodoros_today'

During handling of the above exception, another exception occurred:

Traceback (most recent call last):
  File "/home/timoh/projects/master-o-meter/.venv/lib/python3.9/site-packages/django/template/base.py", line 886, in _resolve_lookup
    if isinstance(current, BaseContext) and getattr(
AttributeError: type object 'RequestContext' has no attribute 'total_pomodoros_today'

During handling of the above exception, another exception occurred:

Traceback (most recent call last):
  File "/home/timoh/projects/master-o-meter/.venv/lib/python3.9/site-packages/django/template/base.py", line 896, in _resolve_lookup
    current = current[int(bit)]
ValueError: invalid literal for int() with base 10: 'total_pomodoros_today'

During handling of the above exception, another exception occurred:

Traceback (most recent call last):
  File "/home/timoh/projects/master-o-meter/.venv/lib/python3.9/site-packages/django/template/base.py", line 903, in _resolve_lookup
    raise VariableDoesNotExist(
django.template.base.VariableDoesNotExist: Failed lookup for key [total_pomodoros_today] in [{'True': True, 'False': False, 'None': None}, {'csrf_token': <SimpleLazyObject: <function csrf.<locals>._get_val at 0xecd23580>>, 'request': <WSGIRequest: GET '/pomo/quest/1/'>, 'user': <SimpleLazyObject: <User: timoh>>, 'perms': PermWrapper(<SimpleLazyObject: <User: timoh>>), 'messages': <FallbackStorage: request=<WSGIRequest: GET '/pomo/quest/1/'>>, 'DEFAULT_MESSAGE_LEVELS': {'DEBUG': 10, 'INFO': 20, 'SUCCESS': 25, 'WARNING': 30, 'ERROR': 40}}, {}, {'quest_name': 'Welcome Ceremony', 'current_step': 0, 'total_steps': 3, 'steps': <QuerySet [<QuestStep: Welcome Ceremony - Step 1>, <QuestStep: Welcome Ceremony - Step 2>, <QuestStep: Welcome Ceremony - Step 3>]>}, {}]
Exception while resolving variable 'event_status' in template 'pomo/quests/base_quest.html'.
Traceback (most recent call last):
  File "/home/timoh/projects/master-o-meter/.venv/lib/python3.9/site-packages/django/template/base.py", line 880, in _resolve_lookup
    current = current[bit]
  File "/home/timoh/projects/master-o-meter/.venv/lib/python3.9/site-packages/django/template/context.py", line 83, in __getitem__
    raise KeyError(key)
KeyError: 'event_status'

During handling of the above exception, another exception occurred:

Traceback (most recent call last):
  File "/home/timoh/projects/master-o-meter/.venv/lib/python3.9/site-packages/django/template/base.py", line 886, in _resolve_lookup
    if isinstance(current, BaseContext) and getattr(
AttributeError: type object 'RequestContext' has no attribute 'event_status'

During handling of the above exception, another exception occurred:

Traceback (most recent call last):
  File "/home/timoh/projects/master-o-meter/.venv/lib/python3.9/site-packages/django/template/base.py", line 896, in _resolve_lookup
    current = current[int(bit)]
ValueError: invalid literal for int() with base 10: 'event_status'

During handling of the above exception, another exception occurred:

Traceback (most recent call last):
  File "/home/timoh/projects/master-o-meter/.venv/lib/python3.9/site-packages/django/template/base.py", line 903, in _resolve_lookup
    raise VariableDoesNotExist(
django.template.base.VariableDoesNotExist: Failed lookup for key [event_status] in [{'True': True, 'False': False, 'None': None}, {'csrf_token': <SimpleLazyObject: <function csrf.<locals>._get_val at 0xecd23580>>, 'request': <WSGIRequest: GET '/pomo/quest/1/'>, 'user': <SimpleLazyObject: <User: timoh>>, 'perms': PermWrapper(<SimpleLazyObject: <User: timoh>>), 'messages': <FallbackStorage: request=<WSGIRequest: GET '/pomo/quest/1/'>>, 'DEFAULT_MESSAGE_LEVELS': {'DEBUG': 10, 'INFO': 20, 'SUCCESS': 25, 'WARNING': 30, 'ERROR': 40}}, {}, {'quest_name': 'Welcome Ceremony', 'current_step': 0, 'total_steps': 3, 'steps': <QuerySet [<QuestStep: Welcome Ceremony - Step 1>, <QuestStep: Welcome Ceremony - Step 2>, <QuestStep: Welcome Ceremony - Step 3>]>}, {'forloop': {'parentloop': {}, 'counter0': 2, 'counter': 3, 'revcounter': 1, 'revcounter0': 0, 'first': False, 'last': True}, 'step': <QuestStep: Welcome Ceremony - Step 3>}]
Not Found: /pomo/quest/1/static/pomo/audio/alarm1.mp3
Exception while resolving variable 'size' in template 'pomo/hub.html'.
Traceback (most recent call last):
  File "/home/timoh/projects/master-o-meter/.venv/lib/python3.9/site-packages/django/template/base.py", line 880, in _resolve_lookup
    current = current[bit]
TypeError: 'Quest' object is not subscriptable

During handling of the above exception, another exception occurred:

Traceback (most recent call last):
  File "/home/timoh/projects/master-o-meter/.venv/lib/python3.9/site-packages/django/template/base.py", line 890, in _resolve_lookup
    current = getattr(current, bit)
AttributeError: 'Quest' object has no attribute 'size'

During handling of the above exception, another exception occurred:

Traceback (most recent call last):
  File "/home/timoh/projects/master-o-meter/.venv/lib/python3.9/site-packages/django/template/base.py", line 896, in _resolve_lookup
    current = current[int(bit)]
ValueError: invalid literal for int() with base 10: 'size'

During handling of the above exception, another exception occurred:

Traceback (most recent call last):
  File "/home/timoh/projects/master-o-meter/.venv/lib/python3.9/site-packages/django/template/base.py", line 903, in _resolve_lookup
    raise VariableDoesNotExist(
django.template.base.VariableDoesNotExist: Failed lookup for key [size] in <Quest: Welcome Ceremony>
Exception while resolving variable 'size' in template 'pomo/hub.html'.
Traceback (most recent call last):
  File "/home/timoh/projects/master-o-meter/.venv/lib/python3.9/site-packages/django/template/base.py", line 880, in _resolve_lookup
    current = current[bit]
TypeError: 'Quest' object is not subscriptable

During handling of the above exception, another exception occurred:

Traceback (most recent call last):
  File "/home/timoh/projects/master-o-meter/.venv/lib/python3.9/site-packages/django/template/base.py", line 890, in _resolve_lookup
    current = getattr(current, bit)
AttributeError: 'Quest' object has no attribute 'size'

During handling of the above exception, another exception occurred:

Traceback (most recent call last):
  File "/home/timoh/projects/master-o-meter/.venv/lib/python3.9/site-packages/django/template/base.py", line 896, in _resolve_lookup
    current = current[int(bit)]
ValueError: invalid literal for int() with base 10: 'size'

During handling of the above exception, another exception occurred:

Traceback (most recent call last):
  File "/home/timoh/projects/master-o-meter/.venv/lib/python3.9/site-packages/django/template/base.py", line 903, in _resolve_lookup
    raise VariableDoesNotExist(
django.template.base.VariableDoesNotExist: Failed lookup for key [size] in <Quest: Welcome Ceremony>
Exception while resolving variable 'size' in template 'pomo/hub.html'.
Traceback (most recent call last):
  File "/home/timoh/projects/master-o-meter/.venv/lib/python3.9/site-packages/django/template/base.py", line 880, in _resolve_lookup
    current = current[bit]
TypeError: 'Quest' object is not subscriptable

During handling of the above exception, another exception occurred:

Traceback (most recent call last):
  File "/home/timoh/projects/master-o-meter/.venv/lib/python3.9/site-packages/django/template/base.py", line 890, in _resolve_lookup
    current = getattr(current, bit)
AttributeError: 'Quest' object has no attribute 'size'

During handling of the above exception, another exception occurred:

Traceback (most recent call last):
  File "/home/timoh/projects/master-o-meter/.venv/lib/python3.9/site-packages/django/template/base.py", line 896, in _resolve_lookup
    current = current[int(bit)]
ValueError: invalid literal for int() with base 10: 'size'

During handling of the above exception, another exception occurred:

Traceback (most recent call last):
  File "/home/timoh/projects/master-o-meter/.venv/lib/python3.9/site-packages/django/template/base.py", line 903, in _resolve_lookup
    raise VariableDoesNotExist(
django.template.base.VariableDoesNotExist: Failed lookup for key [size] in <Quest: Welcome Ceremony>
Exception while resolving variable 'streak' in template 'pomo/quests/base_quest.html'.
Traceback (most recent call last):
  File "/home/timoh/projects/master-o-meter/.venv/lib/python3.9/site-packages/django/template/base.py", line 880, in _resolve_lookup
    current = current[bit]
  File "/home/timoh/projects/master-o-meter/.venv/lib/python3.9/site-packages/django/template/context.py", line 83, in __getitem__
    raise KeyError(key)
KeyError: 'streak'

During handling of the above exception, another exception occurred:

Traceback (most recent call last):
  File "/home/timoh/projects/master-o-meter/.venv/lib/python3.9/site-packages/django/template/base.py", line 886, in _resolve_lookup
    if isinstance(current, BaseContext) and getattr(
AttributeError: type object 'RequestContext' has no attribute 'streak'

During handling of the above exception, another exception occurred:

Traceback (most recent call last):
  File "/home/timoh/projects/master-o-meter/.venv/lib/python3.9/site-packages/django/template/base.py", line 896, in _resolve_lookup
    current = current[int(bit)]
ValueError: invalid literal for int() with base 10: 'streak'

During handling of the above exception, another exception occurred:

Traceback (most recent call last):
  File "/home/timoh/projects/master-o-meter/.venv/lib/python3.9/site-packages/django/template/base.py", line 903, in _resolve_lookup
    raise VariableDoesNotExist(
django.template.base.VariableDoesNotExist: Failed lookup for key [streak] in [{'True': True, 'False': False, 'None': None}, {'csrf_token': <SimpleLazyObject: <function csrf.<locals>._get_val at 0xecbd1c40>>, 'request': <WSGIRequest: GET '/pomo/quest/1/'>, 'user': <SimpleLazyObject: <User: timoh>>, 'perms': PermWrapper(<SimpleLazyObject: <User: timoh>>), 'messages': <FallbackStorage: request=<WSGIRequest: GET '/pomo/quest/1/'>>, 'DEFAULT_MESSAGE_LEVELS': {'DEBUG': 10, 'INFO': 20, 'SUCCESS': 25, 'WARNING': 30, 'ERROR': 40}}, {}, {'quest_name': 'Welcome Ceremony', 'current_step': 0, 'total_steps': 3, 'steps': <QuerySet [<QuestStep: Welcome Ceremony - Step 1>, <QuestStep: Welcome Ceremony - Step 2>, <QuestStep: Welcome Ceremony - Step 3>]>}, {}]
Exception while resolving variable 'total_pomodoros_today' in template 'pomo/quests/base_quest.html'.
Traceback (most recent call last):
  File "/home/timoh/projects/master-o-meter/.venv/lib/python3.9/site-packages/django/template/base.py", line 880, in _resolve_lookup
    current = current[bit]
  File "/home/timoh/projects/master-o-meter/.venv/lib/python3.9/site-packages/django/template/context.py", line 83, in __getitem__
    raise KeyError(key)
KeyError: 'total_pomodoros_today'

During handling of the above exception, another exception occurred:

Traceback (most recent call last):
  File "/home/timoh/projects/master-o-meter/.venv/lib/python3.9/site-packages/django/template/base.py", line 886, in _resolve_lookup
    if isinstance(current, BaseContext) and getattr(
AttributeError: type object 'RequestContext' has no attribute 'total_pomodoros_today'

During handling of the above exception, another exception occurred:

Traceback (most recent call last):
  File "/home/timoh/projects/master-o-meter/.venv/lib/python3.9/site-packages/django/template/base.py", line 896, in _resolve_lookup
    current = current[int(bit)]
ValueError: invalid literal for int() with base 10: 'total_pomodoros_today'

During handling of the above exception, another exception occurred:

Traceback (most recent call last):
  File "/home/timoh/projects/master-o-meter/.venv/lib/python3.9/site-packages/django/template/base.py", line 903, in _resolve_lookup
    raise VariableDoesNotExist(
django.template.base.VariableDoesNotExist: Failed lookup for key [total_pomodoros_today] in [{'True': True, 'False': False, 'None': None}, {'csrf_token': <SimpleLazyObject: <function csrf.<locals>._get_val at 0xecbd1c40>>, 'request': <WSGIRequest: GET '/pomo/quest/1/'>, 'user': <SimpleLazyObject: <User: timoh>>, 'perms': PermWrapper(<SimpleLazyObject: <User: timoh>>), 'messages': <FallbackStorage: request=<WSGIRequest: GET '/pomo/quest/1/'>>, 'DEFAULT_MESSAGE_LEVELS': {'DEBUG': 10, 'INFO': 20, 'SUCCESS': 25, 'WARNING': 30, 'ERROR': 40}}, {}, {'quest_name': 'Welcome Ceremony', 'current_step': 0, 'total_steps': 3, 'steps': <QuerySet [<QuestStep: Welcome Ceremony - Step 1>, <QuestStep: Welcome Ceremony - Step 2>, <QuestStep: Welcome Ceremony - Step 3>]>}, {}]
Exception while resolving variable 'event_status' in template 'pomo/quests/base_quest.html'.
Traceback (most recent call last):
  File "/home/timoh/projects/master-o-meter/.venv/lib/python3.9/site-packages/django/template/base.py", line 880, in _resolve_lookup
    current = current[bit]
  File "/home/timoh/projects/master-o-meter/.venv/lib/python3.9/site-packages/django/template/context.py", line 83, in __getitem__
    raise KeyError(key)
KeyError: 'event_status'

During handling of the above exception, another exception occurred:

Traceback (most recent call last):
  File "/home/timoh/projects/master-o-meter/.venv/lib/python3.9/site-packages/django/template/base.py", line 886, in _resolve_lookup
    if isinstance(current, BaseContext) and getattr(
AttributeError: type object 'RequestContext' has no attribute 'event_status'

During handling of the above exception, another exception occurred:

Traceback (most recent call last):
  File "/home/timoh/projects/master-o-meter/.venv/lib/python3.9/site-packages/django/template/base.py", line 896, in _resolve_lookup
    current = current[int(bit)]
ValueError: invalid literal for int() with base 10: 'event_status'

During handling of the above exception, another exception occurred:

Traceback (most recent call last):
  File "/home/timoh/projects/master-o-meter/.venv/lib/python3.9/site-packages/django/template/base.py", line 903, in _resolve_lookup
    raise VariableDoesNotExist(
django.template.base.VariableDoesNotExist: Failed lookup for key [event_status] in [{'True': True, 'False': False, 'None': None}, {'csrf_token': <SimpleLazyObject: <function csrf.<locals>._get_val at 0xecbd1c40>>, 'request': <WSGIRequest: GET '/pomo/quest/1/'>, 'user': <SimpleLazyObject: <User: timoh>>, 'perms': PermWrapper(<SimpleLazyObject: <User: timoh>>), 'messages': <FallbackStorage: request=<WSGIRequest: GET '/pomo/quest/1/'>>, 'DEFAULT_MESSAGE_LEVELS': {'DEBUG': 10, 'INFO': 20, 'SUCCESS': 25, 'WARNING': 30, 'ERROR': 40}}, {}, {'quest_name': 'Welcome Ceremony', 'current_step': 0, 'total_steps': 3, 'steps': <QuerySet [<QuestStep: Welcome Ceremony - Step 1>, <QuestStep: Welcome Ceremony - Step 2>, <QuestStep: Welcome Ceremony - Step 3>]>}, {'forloop': {'parentloop': {}, 'counter0': 2, 'counter': 3, 'revcounter': 1, 'revcounter0': 0, 'first': False, 'last': True}, 'step': <QuestStep: Welcome Ceremony - Step 3>}]
Not Found: /pomo/quest/1/static/pomo/audio/alarm1.mp3
Exception while resolving variable 'streak' in template 'pomo/quests/base_quest.html'.
Traceback (most recent call last):
  File "/home/timoh/projects/master-o-meter/.venv/lib/python3.9/site-packages/django/template/base.py", line 880, in _resolve_lookup
    current = current[bit]
  File "/home/timoh/projects/master-o-meter/.venv/lib/python3.9/site-packages/django/template/context.py", line 83, in __getitem__
    raise KeyError(key)
KeyError: 'streak'

During handling of the above exception, another exception occurred:

Traceback (most recent call last):
  File "/home/timoh/projects/master-o-meter/.venv/lib/python3.9/site-packages/django/template/base.py", line 886, in _resolve_lookup
    if isinstance(current, BaseContext) and getattr(
AttributeError: type object 'RequestContext' has no attribute 'streak'

During handling of the above exception, another exception occurred:

Traceback (most recent call last):
  File "/home/timoh/projects/master-o-meter/.venv/lib/python3.9/site-packages/django/template/base.py", line 896, in _resolve_lookup
    current = current[int(bit)]
ValueError: invalid literal for int() with base 10: 'streak'

During handling of the above exception, another exception occurred:

Traceback (most recent call last):
  File "/home/timoh/projects/master-o-meter/.venv/lib/python3.9/site-packages/django/template/base.py", line 903, in _resolve_lookup
    raise VariableDoesNotExist(
django.template.base.VariableDoesNotExist: Failed lookup for key [streak] in [{'True': True, 'False': False, 'None': None}, {'csrf_token': <SimpleLazyObject: <function csrf.<locals>._get_val at 0xecb6df10>>, 'request': <WSGIRequest: GET '/pomo/quest/1/'>, 'user': <SimpleLazyObject: <User: timoh>>, 'perms': PermWrapper(<SimpleLazyObject: <User: timoh>>), 'messages': <FallbackStorage: request=<WSGIRequest: GET '/pomo/quest/1/'>>, 'DEFAULT_MESSAGE_LEVELS': {'DEBUG': 10, 'INFO': 20, 'SUCCESS': 25, 'WARNING': 30, 'ERROR': 40}}, {}, {'quest_name': 'Welcome Ceremony', 'current_step': 0, 'total_steps': 3, 'steps': <QuerySet [<QuestStep: Welcome Ceremony - Step 1>, <QuestStep: Welcome Ceremony - Step 2>, <QuestStep: Welcome Ceremony - Step 3>]>}, {}]
Exception while resolving variable 'total_pomodoros_today' in template 'pomo/quests/base_quest.html'.
Traceback (most recent call last):
  File "/home/timoh/projects/master-o-meter/.venv/lib/python3.9/site-packages/django/template/base.py", line 880, in _resolve_lookup
    current = current[bit]
  File "/home/timoh/projects/master-o-meter/.venv/lib/python3.9/site-packages/django/template/context.py", line 83, in __getitem__
    raise KeyError(key)
KeyError: 'total_pomodoros_today'

During handling of the above exception, another exception occurred:

Traceback (most recent call last):
  File "/home/timoh/projects/master-o-meter/.venv/lib/python3.9/site-packages/django/template/base.py", line 886, in _resolve_lookup
    if isinstance(current, BaseContext) and getattr(
AttributeError: type object 'RequestContext' has no attribute 'total_pomodoros_today'

During handling of the above exception, another exception occurred:

Traceback (most recent call last):
  File "/home/timoh/projects/master-o-meter/.venv/lib/python3.9/site-packages/django/template/base.py", line 896, in _resolve_lookup
    current = current[int(bit)]
ValueError: invalid literal for int() with base 10: 'total_pomodoros_today'

During handling of the above exception, another exception occurred:

Traceback (most recent call last):
  File "/home/timoh/projects/master-o-meter/.venv/lib/python3.9/site-packages/django/template/base.py", line 903, in _resolve_lookup
    raise VariableDoesNotExist(
django.template.base.VariableDoesNotExist: Failed lookup for key [total_pomodoros_today] in [{'True': True, 'False': False, 'None': None}, {'csrf_token': <SimpleLazyObject: <function csrf.<locals>._get_val at 0xecb6df10>>, 'request': <WSGIRequest: GET '/pomo/quest/1/'>, 'user': <SimpleLazyObject: <User: timoh>>, 'perms': PermWrapper(<SimpleLazyObject: <User: timoh>>), 'messages': <FallbackStorage: request=<WSGIRequest: GET '/pomo/quest/1/'>>, 'DEFAULT_MESSAGE_LEVELS': {'DEBUG': 10, 'INFO': 20, 'SUCCESS': 25, 'WARNING': 30, 'ERROR': 40}}, {}, {'quest_name': 'Welcome Ceremony', 'current_step': 0, 'total_steps': 3, 'steps': <QuerySet [<QuestStep: Welcome Ceremony - Step 1>, <QuestStep: Welcome Ceremony - Step 2>, <QuestStep: Welcome Ceremony - Step 3>]>}, {}]
Exception while resolving variable 'event_status' in template 'pomo/quests/base_quest.html'.
Traceback (most recent call last):
  File "/home/timoh/projects/master-o-meter/.venv/lib/python3.9/site-packages/django/template/base.py", line 880, in _resolve_lookup
    current = current[bit]
  File "/home/timoh/projects/master-o-meter/.venv/lib/python3.9/site-packages/django/template/context.py", line 83, in __getitem__
    raise KeyError(key)
KeyError: 'event_status'

During handling of the above exception, another exception occurred:

Traceback (most recent call last):
  File "/home/timoh/projects/master-o-meter/.venv/lib/python3.9/site-packages/django/template/base.py", line 886, in _resolve_lookup
    if isinstance(current, BaseContext) and getattr(
AttributeError: type object 'RequestContext' has no attribute 'event_status'

During handling of the above exception, another exception occurred:

Traceback (most recent call last):
  File "/home/timoh/projects/master-o-meter/.venv/lib/python3.9/site-packages/django/template/base.py", line 896, in _resolve_lookup
    current = current[int(bit)]
ValueError: invalid literal for int() with base 10: 'event_status'

During handling of the above exception, another exception occurred:

Traceback (most recent call last):
  File "/home/timoh/projects/master-o-meter/.venv/lib/python3.9/site-packages/django/template/base.py", line 903, in _resolve_lookup
    raise VariableDoesNotExist(
django.template.base.VariableDoesNotExist: Failed lookup for key [event_status] in [{'True': True, 'False': False, 'None': None}, {'csrf_token': <SimpleLazyObject: <function csrf.<locals>._get_val at 0xecb6df10>>, 'request': <WSGIRequest: GET '/pomo/quest/1/'>, 'user': <SimpleLazyObject: <User: timoh>>, 'perms': PermWrapper(<SimpleLazyObject: <User: timoh>>), 'messages': <FallbackStorage: request=<WSGIRequest: GET '/pomo/quest/1/'>>, 'DEFAULT_MESSAGE_LEVELS': {'DEBUG': 10, 'INFO': 20, 'SUCCESS': 25, 'WARNING': 30, 'ERROR': 40}}, {}, {'quest_name': 'Welcome Ceremony', 'current_step': 0, 'total_steps': 3, 'steps': <QuerySet [<QuestStep: Welcome Ceremony - Step 1>, <QuestStep: Welcome Ceremony - Step 2>, <QuestStep: Welcome Ceremony - Step 3>]>}, {'forloop': {'parentloop': {}, 'counter0': 2, 'counter': 3, 'revcounter': 1, 'revcounter0': 0, 'first': False, 'last': True}, 'step': <QuestStep: Welcome Ceremony - Step 3>}]
Not Found: /pomo/quest/1/static/pomo/audio/alarm1.mp3
Exception while resolving variable 'streak' in template 'pomo/quests/base_quest.html'.
Traceback (most recent call last):
  File "/home/timoh/projects/master-o-meter/.venv/lib/python3.9/site-packages/django/template/base.py", line 880, in _resolve_lookup
    current = current[bit]
  File "/home/timoh/projects/master-o-meter/.venv/lib/python3.9/site-packages/django/template/context.py", line 83, in __getitem__
    raise KeyError(key)
KeyError: 'streak'

During handling of the above exception, another exception occurred:

Traceback (most recent call last):
  File "/home/timoh/projects/master-o-meter/.venv/lib/python3.9/site-packages/django/template/base.py", line 886, in _resolve_lookup
    if isinstance(current, BaseContext) and getattr(
AttributeError: type object 'RequestContext' has no attribute 'streak'

During handling of the above exception, another exception occurred:

Traceback (most recent call last):
  File "/home/timoh/projects/master-o-meter/.venv/lib/python3.9/site-packages/django/template/base.py", line 896, in _resolve_lookup
    current = current[int(bit)]
ValueError: invalid literal for int() with base 10: 'streak'

During handling of the above exception, another exception occurred:

Traceback (most recent call last):
  File "/home/timoh/projects/master-o-meter/.venv/lib/python3.9/site-packages/django/template/base.py", line 903, in _resolve_lookup
    raise VariableDoesNotExist(
django.template.base.VariableDoesNotExist: Failed lookup for key [streak] in [{'True': True, 'False': False, 'None': None}, {'csrf_token': <SimpleLazyObject: <function csrf.<locals>._get_val at 0xeced1c40>>, 'request': <WSGIRequest: GET '/pomo/quest/1/'>, 'user': <SimpleLazyObject: <User: timoh>>, 'perms': PermWrapper(<SimpleLazyObject: <User: timoh>>), 'messages': <FallbackStorage: request=<WSGIRequest: GET '/pomo/quest/1/'>>, 'DEFAULT_MESSAGE_LEVELS': {'DEBUG': 10, 'INFO': 20, 'SUCCESS': 25, 'WARNING': 30, 'ERROR': 40}}, {}, {'quest_name': 'Welcome Ceremony', 'current_step': 0, 'total_steps': 3, 'steps': <QuerySet [<QuestStep: Welcome Ceremony - Step 1>, <QuestStep: Welcome Ceremony - Step 2>, <QuestStep: Welcome Ceremony - Step 3>]>}, {}]
Exception while resolving variable 'total_pomodoros_today' in template 'pomo/quests/base_quest.html'.
Traceback (most recent call last):
  File "/home/timoh/projects/master-o-meter/.venv/lib/python3.9/site-packages/django/template/base.py", line 880, in _resolve_lookup
    current = current[bit]
  File "/home/timoh/projects/master-o-meter/.venv/lib/python3.9/site-packages/django/template/context.py", line 83, in __getitem__
    raise KeyError(key)
KeyError: 'total_pomodoros_today'

During handling of the above exception, another exception occurred:

Traceback (most recent call last):
  File "/home/timoh/projects/master-o-meter/.venv/lib/python3.9/site-packages/django/template/base.py", line 886, in _resolve_lookup
    if isinstance(current, BaseContext) and getattr(
AttributeError: type object 'RequestContext' has no attribute 'total_pomodoros_today'

During handling of the above exception, another exception occurred:

Traceback (most recent call last):
  File "/home/timoh/projects/master-o-meter/.venv/lib/python3.9/site-packages/django/template/base.py", line 896, in _resolve_lookup
    current = current[int(bit)]
ValueError: invalid literal for int() with base 10: 'total_pomodoros_today'

During handling of the above exception, another exception occurred:

Traceback (most recent call last):
  File "/home/timoh/projects/master-o-meter/.venv/lib/python3.9/site-packages/django/template/base.py", line 903, in _resolve_lookup
    raise VariableDoesNotExist(
django.template.base.VariableDoesNotExist: Failed lookup for key [total_pomodoros_today] in [{'True': True, 'False': False, 'None': None}, {'csrf_token': <SimpleLazyObject: <function csrf.<locals>._get_val at 0xeced1c40>>, 'request': <WSGIRequest: GET '/pomo/quest/1/'>, 'user': <SimpleLazyObject: <User: timoh>>, 'perms': PermWrapper(<SimpleLazyObject: <User: timoh>>), 'messages': <FallbackStorage: request=<WSGIRequest: GET '/pomo/quest/1/'>>, 'DEFAULT_MESSAGE_LEVELS': {'DEBUG': 10, 'INFO': 20, 'SUCCESS': 25, 'WARNING': 30, 'ERROR': 40}}, {}, {'quest_name': 'Welcome Ceremony', 'current_step': 0, 'total_steps': 3, 'steps': <QuerySet [<QuestStep: Welcome Ceremony - Step 1>, <QuestStep: Welcome Ceremony - Step 2>, <QuestStep: Welcome Ceremony - Step 3>]>}, {}]
Exception while resolving variable 'event_status' in template 'pomo/quests/base_quest.html'.
Traceback (most recent call last):
  File "/home/timoh/projects/master-o-meter/.venv/lib/python3.9/site-packages/django/template/base.py", line 880, in _resolve_lookup
    current = current[bit]
  File "/home/timoh/projects/master-o-meter/.venv/lib/python3.9/site-packages/django/template/context.py", line 83, in __getitem__
    raise KeyError(key)
KeyError: 'event_status'

During handling of the above exception, another exception occurred:

Traceback (most recent call last):
  File "/home/timoh/projects/master-o-meter/.venv/lib/python3.9/site-packages/django/template/base.py", line 886, in _resolve_lookup
    if isinstance(current, BaseContext) and getattr(
AttributeError: type object 'RequestContext' has no attribute 'event_status'

During handling of the above exception, another exception occurred:

Traceback (most recent call last):
  File "/home/timoh/projects/master-o-meter/.venv/lib/python3.9/site-packages/django/template/base.py", line 896, in _resolve_lookup
    current = current[int(bit)]
ValueError: invalid literal for int() with base 10: 'event_status'

During handling of the above exception, another exception occurred:

Traceback (most recent call last):
  File "/home/timoh/projects/master-o-meter/.venv/lib/python3.9/site-packages/django/template/base.py", line 903, in _resolve_lookup
    raise VariableDoesNotExist(
django.template.base.VariableDoesNotExist: Failed lookup for key [event_status] in [{'True': True, 'False': False, 'None': None}, {'csrf_token': <SimpleLazyObject: <function csrf.<locals>._get_val at 0xeced1c40>>, 'request': <WSGIRequest: GET '/pomo/quest/1/'>, 'user': <SimpleLazyObject: <User: timoh>>, 'perms': PermWrapper(<SimpleLazyObject: <User: timoh>>), 'messages': <FallbackStorage: request=<WSGIRequest: GET '/pomo/quest/1/'>>, 'DEFAULT_MESSAGE_LEVELS': {'DEBUG': 10, 'INFO': 20, 'SUCCESS': 25, 'WARNING': 30, 'ERROR': 40}}, {}, {'quest_name': 'Welcome Ceremony', 'current_step': 0, 'total_steps': 3, 'steps': <QuerySet [<QuestStep: Welcome Ceremony - Step 1>, <QuestStep: Welcome Ceremony - Step 2>, <QuestStep: Welcome Ceremony - Step 3>]>}, {'forloop': {'parentloop': {}, 'counter0': 2, 'counter': 3, 'revcounter': 1, 'revcounter0': 0, 'first': False, 'last': True}, 'step': <QuestStep: Welcome Ceremony - Step 3>}]
Not Found: /pomo/quest/1/static/pomo/audio/alarm1.mp3
Exception while resolving variable 'streak' in template 'pomo/quests/base_quest.html'.
Traceback (most recent call last):
  File "/home/timoh/projects/master-o-meter/.venv/lib/python3.9/site-packages/django/template/base.py", line 880, in _resolve_lookup
    current = current[bit]
  File "/home/timoh/projects/master-o-meter/.venv/lib/python3.9/site-packages/django/template/context.py", line 83, in __getitem__
    raise KeyError(key)
KeyError: 'streak'

During handling of the above exception, another exception occurred:

Traceback (most recent call last):
  File "/home/timoh/projects/master-o-meter/.venv/lib/python3.9/site-packages/django/template/base.py", line 886, in _resolve_lookup
    if isinstance(current, BaseContext) and getattr(
AttributeError: type object 'RequestContext' has no attribute 'streak'

During handling of the above exception, another exception occurred:

Traceback (most recent call last):
  File "/home/timoh/projects/master-o-meter/.venv/lib/python3.9/site-packages/django/template/base.py", line 896, in _resolve_lookup
    current = current[int(bit)]
ValueError: invalid literal for int() with base 10: 'streak'

During handling of the above exception, another exception occurred:

Traceback (most recent call last):
  File "/home/timoh/projects/master-o-meter/.venv/lib/python3.9/site-packages/django/template/base.py", line 903, in _resolve_lookup
    raise VariableDoesNotExist(
django.template.base.VariableDoesNotExist: Failed lookup for key [streak] in [{'True': True, 'False': False, 'None': None}, {'csrf_token': <SimpleLazyObject: <function csrf.<locals>._get_val at 0xece91c88>>, 'request': <WSGIRequest: GET '/pomo/quest/1/'>, 'user': <SimpleLazyObject: <User: timoh>>, 'perms': PermWrapper(<SimpleLazyObject: <User: timoh>>), 'messages': <FallbackStorage: request=<WSGIRequest: GET '/pomo/quest/1/'>>, 'DEFAULT_MESSAGE_LEVELS': {'DEBUG': 10, 'INFO': 20, 'SUCCESS': 25, 'WARNING': 30, 'ERROR': 40}}, {}, {'quest_name': 'Welcome Ceremony', 'current_step': 0, 'total_steps': 3, 'steps': <QuerySet [<QuestStep: Welcome Ceremony - Step 1>, <QuestStep: Welcome Ceremony - Step 2>, <QuestStep: Welcome Ceremony - Step 3>]>}, {}]
Exception while resolving variable 'total_pomodoros_today' in template 'pomo/quests/base_quest.html'.
Traceback (most recent call last):
  File "/home/timoh/projects/master-o-meter/.venv/lib/python3.9/site-packages/django/template/base.py", line 880, in _resolve_lookup
    current = current[bit]
  File "/home/timoh/projects/master-o-meter/.venv/lib/python3.9/site-packages/django/template/context.py", line 83, in __getitem__
    raise KeyError(key)
KeyError: 'total_pomodoros_today'

During handling of the above exception, another exception occurred:

Traceback (most recent call last):
  File "/home/timoh/projects/master-o-meter/.venv/lib/python3.9/site-packages/django/template/base.py", line 886, in _resolve_lookup
    if isinstance(current, BaseContext) and getattr(
AttributeError: type object 'RequestContext' has no attribute 'total_pomodoros_today'

During handling of the above exception, another exception occurred:

Traceback (most recent call last):
  File "/home/timoh/projects/master-o-meter/.venv/lib/python3.9/site-packages/django/template/base.py", line 896, in _resolve_lookup
    current = current[int(bit)]
ValueError: invalid literal for int() with base 10: 'total_pomodoros_today'

During handling of the above exception, another exception occurred:

Traceback (most recent call last):
  File "/home/timoh/projects/master-o-meter/.venv/lib/python3.9/site-packages/django/template/base.py", line 903, in _resolve_lookup
    raise VariableDoesNotExist(
django.template.base.VariableDoesNotExist: Failed lookup for key [total_pomodoros_today] in [{'True': True, 'False': False, 'None': None}, {'csrf_token': <SimpleLazyObject: <function csrf.<locals>._get_val at 0xece91c88>>, 'request': <WSGIRequest: GET '/pomo/quest/1/'>, 'user': <SimpleLazyObject: <User: timoh>>, 'perms': PermWrapper(<SimpleLazyObject: <User: timoh>>), 'messages': <FallbackStorage: request=<WSGIRequest: GET '/pomo/quest/1/'>>, 'DEFAULT_MESSAGE_LEVELS': {'DEBUG': 10, 'INFO': 20, 'SUCCESS': 25, 'WARNING': 30, 'ERROR': 40}}, {}, {'quest_name': 'Welcome Ceremony', 'current_step': 0, 'total_steps': 3, 'steps': <QuerySet [<QuestStep: Welcome Ceremony - Step 1>, <QuestStep: Welcome Ceremony - Step 2>, <QuestStep: Welcome Ceremony - Step 3>]>}, {}]
Exception while resolving variable 'event_status' in template 'pomo/quests/base_quest.html'.
Traceback (most recent call last):
  File "/home/timoh/projects/master-o-meter/.venv/lib/python3.9/site-packages/django/template/base.py", line 880, in _resolve_lookup
    current = current[bit]
  File "/home/timoh/projects/master-o-meter/.venv/lib/python3.9/site-packages/django/template/context.py", line 83, in __getitem__
    raise KeyError(key)
KeyError: 'event_status'

During handling of the above exception, another exception occurred:

Traceback (most recent call last):
  File "/home/timoh/projects/master-o-meter/.venv/lib/python3.9/site-packages/django/template/base.py", line 886, in _resolve_lookup
    if isinstance(current, BaseContext) and getattr(
AttributeError: type object 'RequestContext' has no attribute 'event_status'

During handling of the above exception, another exception occurred:

Traceback (most recent call last):
  File "/home/timoh/projects/master-o-meter/.venv/lib/python3.9/site-packages/django/template/base.py", line 896, in _resolve_lookup
    current = current[int(bit)]
ValueError: invalid literal for int() with base 10: 'event_status'

During handling of the above exception, another exception occurred:

Traceback (most recent call last):
  File "/home/timoh/projects/master-o-meter/.venv/lib/python3.9/site-packages/django/template/base.py", line 903, in _resolve_lookup
    raise VariableDoesNotExist(
django.template.base.VariableDoesNotExist: Failed lookup for key [event_status] in [{'True': True, 'False': False, 'None': None}, {'csrf_token': <SimpleLazyObject: <function csrf.<locals>._get_val at 0xece91c88>>, 'request': <WSGIRequest: GET '/pomo/quest/1/'>, 'user': <SimpleLazyObject: <User: timoh>>, 'perms': PermWrapper(<SimpleLazyObject: <User: timoh>>), 'messages': <FallbackStorage: request=<WSGIRequest: GET '/pomo/quest/1/'>>, 'DEFAULT_MESSAGE_LEVELS': {'DEBUG': 10, 'INFO': 20, 'SUCCESS': 25, 'WARNING': 30, 'ERROR': 40}}, {}, {'quest_name': 'Welcome Ceremony', 'current_step': 0, 'total_steps': 3, 'steps': <QuerySet [<QuestStep: Welcome Ceremony - Step 1>, <QuestStep: Welcome Ceremony - Step 2>, <QuestStep: Welcome Ceremony - Step 3>]>}, {'forloop': {'parentloop': {}, 'counter0': 2, 'counter': 3, 'revcounter': 1, 'revcounter0': 0, 'first': False, 'last': True}, 'step': <QuestStep: Welcome Ceremony - Step 3>}]
Not Found: /pomo/quest/1/static/pomo/audio/alarm1.mp3
Exception while resolving variable 'streak' in template 'pomo/quests/base_quest.html'.
Traceback (most recent call last):
  File "/home/timoh/projects/master-o-meter/.venv/lib/python3.9/site-packages/django/template/base.py", line 880, in _resolve_lookup
    current = current[bit]
  File "/home/timoh/projects/master-o-meter/.venv/lib/python3.9/site-packages/django/template/context.py", line 83, in __getitem__
    raise KeyError(key)
KeyError: 'streak'

During handling of the above exception, another exception occurred:

Traceback (most recent call last):
  File "/home/timoh/projects/master-o-meter/.venv/lib/python3.9/site-packages/django/template/base.py", line 886, in _resolve_lookup
    if isinstance(current, BaseContext) and getattr(
AttributeError: type object 'RequestContext' has no attribute 'streak'

During handling of the above exception, another exception occurred:

Traceback (most recent call last):
  File "/home/timoh/projects/master-o-meter/.venv/lib/python3.9/site-packages/django/template/base.py", line 896, in _resolve_lookup
    current = current[int(bit)]
ValueError: invalid literal for int() with base 10: 'streak'

During handling of the above exception, another exception occurred:

Traceback (most recent call last):
  File "/home/timoh/projects/master-o-meter/.venv/lib/python3.9/site-packages/django/template/base.py", line 903, in _resolve_lookup
    raise VariableDoesNotExist(
django.template.base.VariableDoesNotExist: Failed lookup for key [streak] in [{'True': True, 'False': False, 'None': None}, {'csrf_token': <SimpleLazyObject: <function csrf.<locals>._get_val at 0xece2ae80>>, 'request': <WSGIRequest: GET '/pomo/quest/1/'>, 'user': <SimpleLazyObject: <User: timoh>>, 'perms': PermWrapper(<SimpleLazyObject: <User: timoh>>), 'messages': <FallbackStorage: request=<WSGIRequest: GET '/pomo/quest/1/'>>, 'DEFAULT_MESSAGE_LEVELS': {'DEBUG': 10, 'INFO': 20, 'SUCCESS': 25, 'WARNING': 30, 'ERROR': 40}}, {}, {'quest_name': 'Welcome Ceremony', 'current_step': 0, 'total_steps': 3, 'steps': <QuerySet [<QuestStep: Welcome Ceremony - Step 1>, <QuestStep: Welcome Ceremony - Step 2>, <QuestStep: Welcome Ceremony - Step 3>]>}, {}]
Exception while resolving variable 'total_pomodoros_today' in template 'pomo/quests/base_quest.html'.
Traceback (most recent call last):
  File "/home/timoh/projects/master-o-meter/.venv/lib/python3.9/site-packages/django/template/base.py", line 880, in _resolve_lookup
    current = current[bit]
  File "/home/timoh/projects/master-o-meter/.venv/lib/python3.9/site-packages/django/template/context.py", line 83, in __getitem__
    raise KeyError(key)
KeyError: 'total_pomodoros_today'

During handling of the above exception, another exception occurred:

Traceback (most recent call last):
  File "/home/timoh/projects/master-o-meter/.venv/lib/python3.9/site-packages/django/template/base.py", line 886, in _resolve_lookup
    if isinstance(current, BaseContext) and getattr(
AttributeError: type object 'RequestContext' has no attribute 'total_pomodoros_today'

During handling of the above exception, another exception occurred:

Traceback (most recent call last):
  File "/home/timoh/projects/master-o-meter/.venv/lib/python3.9/site-packages/django/template/base.py", line 896, in _resolve_lookup
    current = current[int(bit)]
ValueError: invalid literal for int() with base 10: 'total_pomodoros_today'

During handling of the above exception, another exception occurred:

Traceback (most recent call last):
  File "/home/timoh/projects/master-o-meter/.venv/lib/python3.9/site-packages/django/template/base.py", line 903, in _resolve_lookup
    raise VariableDoesNotExist(
django.template.base.VariableDoesNotExist: Failed lookup for key [total_pomodoros_today] in [{'True': True, 'False': False, 'None': None}, {'csrf_token': <SimpleLazyObject: <function csrf.<locals>._get_val at 0xece2ae80>>, 'request': <WSGIRequest: GET '/pomo/quest/1/'>, 'user': <SimpleLazyObject: <User: timoh>>, 'perms': PermWrapper(<SimpleLazyObject: <User: timoh>>), 'messages': <FallbackStorage: request=<WSGIRequest: GET '/pomo/quest/1/'>>, 'DEFAULT_MESSAGE_LEVELS': {'DEBUG': 10, 'INFO': 20, 'SUCCESS': 25, 'WARNING': 30, 'ERROR': 40}}, {}, {'quest_name': 'Welcome Ceremony', 'current_step': 0, 'total_steps': 3, 'steps': <QuerySet [<QuestStep: Welcome Ceremony - Step 1>, <QuestStep: Welcome Ceremony - Step 2>, <QuestStep: Welcome Ceremony - Step 3>]>}, {}]
Exception while resolving variable 'event_status' in template 'pomo/quests/base_quest.html'.
Traceback (most recent call last):
  File "/home/timoh/projects/master-o-meter/.venv/lib/python3.9/site-packages/django/template/base.py", line 880, in _resolve_lookup
    current = current[bit]
  File "/home/timoh/projects/master-o-meter/.venv/lib/python3.9/site-packages/django/template/context.py", line 83, in __getitem__
    raise KeyError(key)
KeyError: 'event_status'

During handling of the above exception, another exception occurred:

Traceback (most recent call last):
  File "/home/timoh/projects/master-o-meter/.venv/lib/python3.9/site-packages/django/template/base.py", line 886, in _resolve_lookup
    if isinstance(current, BaseContext) and getattr(
AttributeError: type object 'RequestContext' has no attribute 'event_status'

During handling of the above exception, another exception occurred:

Traceback (most recent call last):
  File "/home/timoh/projects/master-o-meter/.venv/lib/python3.9/site-packages/django/template/base.py", line 896, in _resolve_lookup
    current = current[int(bit)]
ValueError: invalid literal for int() with base 10: 'event_status'

During handling of the above exception, another exception occurred:

Traceback (most recent call last):
  File "/home/timoh/projects/master-o-meter/.venv/lib/python3.9/site-packages/django/template/base.py", line 903, in _resolve_lookup
    raise VariableDoesNotExist(
django.template.base.VariableDoesNotExist: Failed lookup for key [event_status] in [{'True': True, 'False': False, 'None': None}, {'csrf_token': <SimpleLazyObject: <function csrf.<locals>._get_val at 0xece2ae80>>, 'request': <WSGIRequest: GET '/pomo/quest/1/'>, 'user': <SimpleLazyObject: <User: timoh>>, 'perms': PermWrapper(<SimpleLazyObject: <User: timoh>>), 'messages': <FallbackStorage: request=<WSGIRequest: GET '/pomo/quest/1/'>>, 'DEFAULT_MESSAGE_LEVELS': {'DEBUG': 10, 'INFO': 20, 'SUCCESS': 25, 'WARNING': 30, 'ERROR': 40}}, {}, {'quest_name': 'Welcome Ceremony', 'current_step': 0, 'total_steps': 3, 'steps': <QuerySet [<QuestStep: Welcome Ceremony - Step 1>, <QuestStep: Welcome Ceremony - Step 2>, <QuestStep: Welcome Ceremony - Step 3>]>}, {'forloop': {'parentloop': {}, 'counter0': 2, 'counter': 3, 'revcounter': 1, 'revcounter0': 0, 'first': False, 'last': True}, 'step': <QuestStep: Welcome Ceremony - Step 3>}]
Not Found: /pomo/quest/1/static/pomo/audio/alarm1.mp3
Exception while resolving variable 'streak' in template 'pomo/quests/base_quest.html'.
Traceback (most recent call last):
  File "/home/timoh/projects/master-o-meter/.venv/lib/python3.9/site-packages/django/template/base.py", line 880, in _resolve_lookup
    current = current[bit]
  File "/home/timoh/projects/master-o-meter/.venv/lib/python3.9/site-packages/django/template/context.py", line 83, in __getitem__
    raise KeyError(key)
KeyError: 'streak'

During handling of the above exception, another exception occurred:

Traceback (most recent call last):
  File "/home/timoh/projects/master-o-meter/.venv/lib/python3.9/site-packages/django/template/base.py", line 886, in _resolve_lookup
    if isinstance(current, BaseContext) and getattr(
AttributeError: type object 'RequestContext' has no attribute 'streak'

During handling of the above exception, another exception occurred:

Traceback (most recent call last):
  File "/home/timoh/projects/master-o-meter/.venv/lib/python3.9/site-packages/django/template/base.py", line 896, in _resolve_lookup
    current = current[int(bit)]
ValueError: invalid literal for int() with base 10: 'streak'

During handling of the above exception, another exception occurred:

Traceback (most recent call last):
  File "/home/timoh/projects/master-o-meter/.venv/lib/python3.9/site-packages/django/template/base.py", line 903, in _resolve_lookup
    raise VariableDoesNotExist(
django.template.base.VariableDoesNotExist: Failed lookup for key [streak] in [{'True': True, 'False': False, 'None': None}, {'csrf_token': <SimpleLazyObject: <function csrf.<locals>._get_val at 0xece2ae38>>, 'request': <WSGIRequest: GET '/pomo/quest/1/'>, 'user': <SimpleLazyObject: <User: timoh>>, 'perms': PermWrapper(<SimpleLazyObject: <User: timoh>>), 'messages': <FallbackStorage: request=<WSGIRequest: GET '/pomo/quest/1/'>>, 'DEFAULT_MESSAGE_LEVELS': {'DEBUG': 10, 'INFO': 20, 'SUCCESS': 25, 'WARNING': 30, 'ERROR': 40}}, {}, {'quest_name': 'Welcome Ceremony', 'current_step': 0, 'total_steps': 3, 'steps': <QuerySet [<QuestStep: Welcome Ceremony - Step 1>, <QuestStep: Welcome Ceremony - Step 2>, <QuestStep: Welcome Ceremony - Step 3>]>}, {}]
Exception while resolving variable 'total_pomodoros_today' in template 'pomo/quests/base_quest.html'.
Traceback (most recent call last):
  File "/home/timoh/projects/master-o-meter/.venv/lib/python3.9/site-packages/django/template/base.py", line 880, in _resolve_lookup
    current = current[bit]
  File "/home/timoh/projects/master-o-meter/.venv/lib/python3.9/site-packages/django/template/context.py", line 83, in __getitem__
    raise KeyError(key)
KeyError: 'total_pomodoros_today'

During handling of the above exception, another exception occurred:

Traceback (most recent call last):
  File "/home/timoh/projects/master-o-meter/.venv/lib/python3.9/site-packages/django/template/base.py", line 886, in _resolve_lookup
    if isinstance(current, BaseContext) and getattr(
AttributeError: type object 'RequestContext' has no attribute 'total_pomodoros_today'

During handling of the above exception, another exception occurred:

Traceback (most recent call last):
  File "/home/timoh/projects/master-o-meter/.venv/lib/python3.9/site-packages/django/template/base.py", line 896, in _resolve_lookup
    current = current[int(bit)]
ValueError: invalid literal for int() with base 10: 'total_pomodoros_today'

During handling of the above exception, another exception occurred:

Traceback (most recent call last):
  File "/home/timoh/projects/master-o-meter/.venv/lib/python3.9/site-packages/django/template/base.py", line 903, in _resolve_lookup
    raise VariableDoesNotExist(
django.template.base.VariableDoesNotExist: Failed lookup for key [total_pomodoros_today] in [{'True': True, 'False': False, 'None': None}, {'csrf_token': <SimpleLazyObject: <function csrf.<locals>._get_val at 0xece2ae38>>, 'request': <WSGIRequest: GET '/pomo/quest/1/'>, 'user': <SimpleLazyObject: <User: timoh>>, 'perms': PermWrapper(<SimpleLazyObject: <User: timoh>>), 'messages': <FallbackStorage: request=<WSGIRequest: GET '/pomo/quest/1/'>>, 'DEFAULT_MESSAGE_LEVELS': {'DEBUG': 10, 'INFO': 20, 'SUCCESS': 25, 'WARNING': 30, 'ERROR': 40}}, {}, {'quest_name': 'Welcome Ceremony', 'current_step': 0, 'total_steps': 3, 'steps': <QuerySet [<QuestStep: Welcome Ceremony - Step 1>, <QuestStep: Welcome Ceremony - Step 2>, <QuestStep: Welcome Ceremony - Step 3>]>}, {}]
Exception while resolving variable 'event_status' in template 'pomo/quests/base_quest.html'.
Traceback (most recent call last):
  File "/home/timoh/projects/master-o-meter/.venv/lib/python3.9/site-packages/django/template/base.py", line 880, in _resolve_lookup
    current = current[bit]
  File "/home/timoh/projects/master-o-meter/.venv/lib/python3.9/site-packages/django/template/context.py", line 83, in __getitem__
    raise KeyError(key)
KeyError: 'event_status'

During handling of the above exception, another exception occurred:

Traceback (most recent call last):
  File "/home/timoh/projects/master-o-meter/.venv/lib/python3.9/site-packages/django/template/base.py", line 886, in _resolve_lookup
    if isinstance(current, BaseContext) and getattr(
AttributeError: type object 'RequestContext' has no attribute 'event_status'

During handling of the above exception, another exception occurred:

Traceback (most recent call last):
  File "/home/timoh/projects/master-o-meter/.venv/lib/python3.9/site-packages/django/template/base.py", line 896, in _resolve_lookup
    current = current[int(bit)]
ValueError: invalid literal for int() with base 10: 'event_status'

During handling of the above exception, another exception occurred:

Traceback (most recent call last):
  File "/home/timoh/projects/master-o-meter/.venv/lib/python3.9/site-packages/django/template/base.py", line 903, in _resolve_lookup
    raise VariableDoesNotExist(
django.template.base.VariableDoesNotExist: Failed lookup for key [event_status] in [{'True': True, 'False': False, 'None': None}, {'csrf_token': <SimpleLazyObject: <function csrf.<locals>._get_val at 0xece2ae38>>, 'request': <WSGIRequest: GET '/pomo/quest/1/'>, 'user': <SimpleLazyObject: <User: timoh>>, 'perms': PermWrapper(<SimpleLazyObject: <User: timoh>>), 'messages': <FallbackStorage: request=<WSGIRequest: GET '/pomo/quest/1/'>>, 'DEFAULT_MESSAGE_LEVELS': {'DEBUG': 10, 'INFO': 20, 'SUCCESS': 25, 'WARNING': 30, 'ERROR': 40}}, {}, {'quest_name': 'Welcome Ceremony', 'current_step': 0, 'total_steps': 3, 'steps': <QuerySet [<QuestStep: Welcome Ceremony - Step 1>, <QuestStep: Welcome Ceremony - Step 2>, <QuestStep: Welcome Ceremony - Step 3>]>}, {'forloop': {'parentloop': {}, 'counter0': 2, 'counter': 3, 'revcounter': 1, 'revcounter0': 0, 'first': False, 'last': True}, 'step': <QuestStep: Welcome Ceremony - Step 3>}]
Not Found: /pomo/quest/1/static/pomo/audio/alarm1.mp3
