Exception while resolving variable 'player_state_json' in template 'pomo/map.html'.
Traceback (most recent call last):
  File "/home/timoh/projects/master-o-meter/.venv/lib/python3.9/site-packages/django/template/base.py", line 880, in _resolve_lookup
    current = current[bit]
  File "/home/timoh/projects/master-o-meter/.venv/lib/python3.9/site-packages/django/template/context.py", line 83, in __getitem__
    raise KeyError(key)
KeyError: 'player_state_json'

During handling of the above exception, another exception occurred:

Traceback (most recent call last):
  File "/home/timoh/projects/master-o-meter/.venv/lib/python3.9/site-packages/django/template/base.py", line 886, in _resolve_lookup
    if isinstance(current, BaseContext) and getattr(
AttributeError: type object 'RequestContext' has no attribute 'player_state_json'

During handling of the above exception, another exception occurred:

Traceback (most recent call last):
  File "/home/timoh/projects/master-o-meter/.venv/lib/python3.9/site-packages/django/template/base.py", line 896, in _resolve_lookup
    current = current[int(bit)]
ValueError: invalid literal for int() with base 10: 'player_state_json'

During handling of the above exception, another exception occurred:

Traceback (most recent call last):
  File "/home/timoh/projects/master-o-meter/.venv/lib/python3.9/site-packages/django/template/base.py", line 903, in _resolve_lookup
    raise VariableDoesNotExist(
django.template.base.VariableDoesNotExist: Failed lookup for key [player_state_json] in [{'True': True, 'False': False, 'None': None}, {'csrf_token': <SimpleLazyObject: '4hLegAZ5WulgwW4S5QDyswXF8xuxq6R933IoKMj7G7Y3PzQvM3E0VLn3vR5lcv4Z'>, 'request': <WSGIRequest: GET '/pomo/'>, 'user': <SimpleLazyObject: <User: developer>>, 'perms': PermWrapper(<SimpleLazyObject: <User: developer>>), 'messages': <FallbackStorage: request=<WSGIRequest: GET '/pomo/'>>, 'DEFAULT_MESSAGE_LEVELS': {'DEBUG': 10, 'INFO': 20, 'SUCCESS': 25, 'WARNING': 30, 'ERROR': 40}}, {}, {'total_pomos_alltime': 25, 'total_pomodoros_today': 0, 'streak': 3, 'is_developer': True, 'username': 'developer'}]
Exception while resolving variable 'location_states_json' in template 'pomo/map.html'.
Traceback (most recent call last):
  File "/home/timoh/projects/master-o-meter/.venv/lib/python3.9/site-packages/django/template/base.py", line 880, in _resolve_lookup
    current = current[bit]
  File "/home/timoh/projects/master-o-meter/.venv/lib/python3.9/site-packages/django/template/context.py", line 83, in __getitem__
    raise KeyError(key)
KeyError: 'location_states_json'

During handling of the above exception, another exception occurred:

Traceback (most recent call last):
  File "/home/timoh/projects/master-o-meter/.venv/lib/python3.9/site-packages/django/template/base.py", line 886, in _resolve_lookup
    if isinstance(current, BaseContext) and getattr(
AttributeError: type object 'RequestContext' has no attribute 'location_states_json'

During handling of the above exception, another exception occurred:

Traceback (most recent call last):
  File "/home/timoh/projects/master-o-meter/.venv/lib/python3.9/site-packages/django/template/base.py", line 896, in _resolve_lookup
    current = current[int(bit)]
ValueError: invalid literal for int() with base 10: 'location_states_json'

During handling of the above exception, another exception occurred:

Traceback (most recent call last):
  File "/home/timoh/projects/master-o-meter/.venv/lib/python3.9/site-packages/django/template/base.py", line 903, in _resolve_lookup
    raise VariableDoesNotExist(
django.template.base.VariableDoesNotExist: Failed lookup for key [location_states_json] in [{'True': True, 'False': False, 'None': None}, {'csrf_token': <SimpleLazyObject: '4hLegAZ5WulgwW4S5QDyswXF8xuxq6R933IoKMj7G7Y3PzQvM3E0VLn3vR5lcv4Z'>, 'request': <WSGIRequest: GET '/pomo/'>, 'user': <SimpleLazyObject: <User: developer>>, 'perms': PermWrapper(<SimpleLazyObject: <User: developer>>), 'messages': <FallbackStorage: request=<WSGIRequest: GET '/pomo/'>>, 'DEFAULT_MESSAGE_LEVELS': {'DEBUG': 10, 'INFO': 20, 'SUCCESS': 25, 'WARNING': 30, 'ERROR': 40}}, {}, {'total_pomos_alltime': 25, 'total_pomodoros_today': 0, 'streak': 3, 'is_developer': True, 'username': 'developer'}]
Not Found: /favicon.ico
Exception while resolving variable 'player_state_json' in template 'pomo/map.html'.
Traceback (most recent call last):
  File "/home/timoh/projects/master-o-meter/.venv/lib/python3.9/site-packages/django/template/base.py", line 880, in _resolve_lookup
    current = current[bit]
  File "/home/timoh/projects/master-o-meter/.venv/lib/python3.9/site-packages/django/template/context.py", line 83, in __getitem__
    raise KeyError(key)
KeyError: 'player_state_json'

During handling of the above exception, another exception occurred:

Traceback (most recent call last):
  File "/home/timoh/projects/master-o-meter/.venv/lib/python3.9/site-packages/django/template/base.py", line 886, in _resolve_lookup
    if isinstance(current, BaseContext) and getattr(
AttributeError: type object 'RequestContext' has no attribute 'player_state_json'

During handling of the above exception, another exception occurred:

Traceback (most recent call last):
  File "/home/timoh/projects/master-o-meter/.venv/lib/python3.9/site-packages/django/template/base.py", line 896, in _resolve_lookup
    current = current[int(bit)]
ValueError: invalid literal for int() with base 10: 'player_state_json'

During handling of the above exception, another exception occurred:

Traceback (most recent call last):
  File "/home/timoh/projects/master-o-meter/.venv/lib/python3.9/site-packages/django/template/base.py", line 903, in _resolve_lookup
    raise VariableDoesNotExist(
django.template.base.VariableDoesNotExist: Failed lookup for key [player_state_json] in [{'True': True, 'False': False, 'None': None}, {'csrf_token': <SimpleLazyObject: 'FH2M4Z37bSAqn9BXo7jA6zplbL6WldfAv7sV2MUutfthQg3twGD5mABv8QSNg1vB'>, 'request': <WSGIRequest: GET '/pomo/'>, 'user': <SimpleLazyObject: <User: developer>>, 'perms': PermWrapper(<SimpleLazyObject: <User: developer>>), 'messages': <FallbackStorage: request=<WSGIRequest: GET '/pomo/'>>, 'DEFAULT_MESSAGE_LEVELS': {'DEBUG': 10, 'INFO': 20, 'SUCCESS': 25, 'WARNING': 30, 'ERROR': 40}}, {}, {'total_pomos_alltime': 25, 'total_pomodoros_today': 0, 'streak': 3, 'is_developer': True, 'username': 'developer'}]
Exception while resolving variable 'location_states_json' in template 'pomo/map.html'.
Traceback (most recent call last):
  File "/home/timoh/projects/master-o-meter/.venv/lib/python3.9/site-packages/django/template/base.py", line 880, in _resolve_lookup
    current = current[bit]
  File "/home/timoh/projects/master-o-meter/.venv/lib/python3.9/site-packages/django/template/context.py", line 83, in __getitem__
    raise KeyError(key)
KeyError: 'location_states_json'

During handling of the above exception, another exception occurred:

Traceback (most recent call last):
  File "/home/timoh/projects/master-o-meter/.venv/lib/python3.9/site-packages/django/template/base.py", line 886, in _resolve_lookup
    if isinstance(current, BaseContext) and getattr(
AttributeError: type object 'RequestContext' has no attribute 'location_states_json'

During handling of the above exception, another exception occurred:

Traceback (most recent call last):
  File "/home/timoh/projects/master-o-meter/.venv/lib/python3.9/site-packages/django/template/base.py", line 896, in _resolve_lookup
    current = current[int(bit)]
ValueError: invalid literal for int() with base 10: 'location_states_json'

During handling of the above exception, another exception occurred:

Traceback (most recent call last):
  File "/home/timoh/projects/master-o-meter/.venv/lib/python3.9/site-packages/django/template/base.py", line 903, in _resolve_lookup
    raise VariableDoesNotExist(
django.template.base.VariableDoesNotExist: Failed lookup for key [location_states_json] in [{'True': True, 'False': False, 'None': None}, {'csrf_token': <SimpleLazyObject: 'FH2M4Z37bSAqn9BXo7jA6zplbL6WldfAv7sV2MUutfthQg3twGD5mABv8QSNg1vB'>, 'request': <WSGIRequest: GET '/pomo/'>, 'user': <SimpleLazyObject: <User: developer>>, 'perms': PermWrapper(<SimpleLazyObject: <User: developer>>), 'messages': <FallbackStorage: request=<WSGIRequest: GET '/pomo/'>>, 'DEFAULT_MESSAGE_LEVELS': {'DEBUG': 10, 'INFO': 20, 'SUCCESS': 25, 'WARNING': 30, 'ERROR': 40}}, {}, {'total_pomos_alltime': 25, 'total_pomodoros_today': 0, 'streak': 3, 'is_developer': True, 'username': 'developer'}]
Error creating PartnerQuest: unsupported operand type(s) for +: 'NoneType' and 'datetime.timedelta'
Internal Server Error: /pomo/accept_partner_quest/3/
Traceback (most recent call last):
  File "/home/timoh/projects/master-o-meter/webapp/pomo/views.py", line 47, in accept_partner_quest
    PartnerQuest.objects.create(
  File "/home/timoh/projects/master-o-meter/.venv/lib/python3.9/site-packages/django/db/models/manager.py", line 87, in manager_method
    return getattr(self.get_queryset(), name)(*args, **kwargs)
  File "/home/timoh/projects/master-o-meter/.venv/lib/python3.9/site-packages/django/db/models/query.py", line 658, in create
    obj.save(force_insert=True, using=self.db)
  File "/home/timoh/projects/master-o-meter/webapp/pomo/models.py", line 49, in save
    self.end_time = self.start_time + timedelta(hours=72)
TypeError: unsupported operand type(s) for +: 'NoneType' and 'datetime.timedelta'

During handling of the above exception, another exception occurred:

Traceback (most recent call last):
  File "/home/timoh/projects/master-o-meter/.venv/lib/python3.9/site-packages/django/core/handlers/exception.py", line 55, in inner
    response = get_response(request)
  File "/home/timoh/projects/master-o-meter/.venv/lib/python3.9/site-packages/django/core/handlers/base.py", line 197, in _get_response
    response = wrapped_callback(request, *callback_args, **callback_kwargs)
  File "/home/timoh/projects/master-o-meter/.venv/lib/python3.9/site-packages/django/contrib/auth/decorators.py", line 23, in _wrapper_view
    return view_func(request, *args, **kwargs)
  File "/home/timoh/projects/master-o-meter/webapp/pomo/views.py", line 55, in accept_partner_quest
    return redirect('common_rooms', error="Could not create PartnerQuest")
  File "/home/timoh/projects/master-o-meter/.venv/lib/python3.9/site-packages/django/shortcuts.py", line 48, in redirect
    return redirect_class(resolve_url(to, *args, **kwargs))
  File "/home/timoh/projects/master-o-meter/.venv/lib/python3.9/site-packages/django/shortcuts.py", line 145, in resolve_url
    return reverse(to, args=args, kwargs=kwargs)
  File "/home/timoh/projects/master-o-meter/.venv/lib/python3.9/site-packages/django/urls/base.py", line 88, in reverse
    return resolver._reverse_with_prefix(view, prefix, *args, **kwargs)
  File "/home/timoh/projects/master-o-meter/.venv/lib/python3.9/site-packages/django/urls/resolvers.py", line 828, in _reverse_with_prefix
    raise NoReverseMatch(msg)
django.urls.exceptions.NoReverseMatch: Reverse for 'common_rooms' with keyword arguments '{'error': 'Could not create PartnerQuest'}' not found. 1 pattern(s) tried: ['pomo/common_rooms/\\Z']
Exception while resolving variable 'partner1_progress' in template 'pomo/common_rooms.html'.
Traceback (most recent call last):
  File "/home/timoh/projects/master-o-meter/.venv/lib/python3.9/site-packages/django/template/base.py", line 880, in _resolve_lookup
    current = current[bit]
KeyError: 'partner1_progress'

During handling of the above exception, another exception occurred:

Traceback (most recent call last):
  File "/home/timoh/projects/master-o-meter/.venv/lib/python3.9/site-packages/django/template/base.py", line 890, in _resolve_lookup
    current = getattr(current, bit)
AttributeError: 'dict' object has no attribute 'partner1_progress'

During handling of the above exception, another exception occurred:

Traceback (most recent call last):
  File "/home/timoh/projects/master-o-meter/.venv/lib/python3.9/site-packages/django/template/base.py", line 896, in _resolve_lookup
    current = current[int(bit)]
ValueError: invalid literal for int() with base 10: 'partner1_progress'

During handling of the above exception, another exception occurred:

Traceback (most recent call last):
  File "/home/timoh/projects/master-o-meter/.venv/lib/python3.9/site-packages/django/template/base.py", line 903, in _resolve_lookup
    raise VariableDoesNotExist(
django.template.base.VariableDoesNotExist: Failed lookup for key [partner1_progress] in {'partner1': 'developer2', 'partner2': 'developer', 'start_time': datetime.datetime(2025, 1, 5, 15, 52, 49, 883013, tzinfo=datetime.timezone.utc), 'end_time': datetime.datetime(2025, 1, 8, 15, 52, 49, 882451, tzinfo=datetime.timezone.utc), 'size': 250, 'progress_partner1': 0, 'progress_partner2': 0, 'is_open': True}
Exception while resolving variable 'partner2_progress' in template 'pomo/common_rooms.html'.
Traceback (most recent call last):
  File "/home/timoh/projects/master-o-meter/.venv/lib/python3.9/site-packages/django/template/base.py", line 880, in _resolve_lookup
    current = current[bit]
KeyError: 'partner2_progress'

During handling of the above exception, another exception occurred:

Traceback (most recent call last):
  File "/home/timoh/projects/master-o-meter/.venv/lib/python3.9/site-packages/django/template/base.py", line 890, in _resolve_lookup
    current = getattr(current, bit)
AttributeError: 'dict' object has no attribute 'partner2_progress'

During handling of the above exception, another exception occurred:

Traceback (most recent call last):
  File "/home/timoh/projects/master-o-meter/.venv/lib/python3.9/site-packages/django/template/base.py", line 896, in _resolve_lookup
    current = current[int(bit)]
ValueError: invalid literal for int() with base 10: 'partner2_progress'

During handling of the above exception, another exception occurred:

Traceback (most recent call last):
  File "/home/timoh/projects/master-o-meter/.venv/lib/python3.9/site-packages/django/template/base.py", line 903, in _resolve_lookup
    raise VariableDoesNotExist(
django.template.base.VariableDoesNotExist: Failed lookup for key [partner2_progress] in {'partner1': 'developer2', 'partner2': 'developer', 'start_time': datetime.datetime(2025, 1, 5, 15, 52, 49, 883013, tzinfo=datetime.timezone.utc), 'end_time': datetime.datetime(2025, 1, 8, 15, 52, 49, 882451, tzinfo=datetime.timezone.utc), 'size': 250, 'progress_partner1': 0, 'progress_partner2': 0, 'is_open': True}
Exception while resolving variable 'is_completed' in template 'pomo/common_rooms.html'.
Traceback (most recent call last):
  File "/home/timoh/projects/master-o-meter/.venv/lib/python3.9/site-packages/django/template/base.py", line 880, in _resolve_lookup
    current = current[bit]
KeyError: 'is_completed'

During handling of the above exception, another exception occurred:

Traceback (most recent call last):
  File "/home/timoh/projects/master-o-meter/.venv/lib/python3.9/site-packages/django/template/base.py", line 890, in _resolve_lookup
    current = getattr(current, bit)
AttributeError: 'dict' object has no attribute 'is_completed'

During handling of the above exception, another exception occurred:

Traceback (most recent call last):
  File "/home/timoh/projects/master-o-meter/.venv/lib/python3.9/site-packages/django/template/base.py", line 896, in _resolve_lookup
    current = current[int(bit)]
ValueError: invalid literal for int() with base 10: 'is_completed'

During handling of the above exception, another exception occurred:

Traceback (most recent call last):
  File "/home/timoh/projects/master-o-meter/.venv/lib/python3.9/site-packages/django/template/base.py", line 903, in _resolve_lookup
    raise VariableDoesNotExist(
django.template.base.VariableDoesNotExist: Failed lookup for key [is_completed] in {'partner1': 'developer2', 'partner2': 'developer', 'start_time': datetime.datetime(2025, 1, 5, 15, 52, 49, 883013, tzinfo=datetime.timezone.utc), 'end_time': datetime.datetime(2025, 1, 8, 15, 52, 49, 882451, tzinfo=datetime.timezone.utc), 'size': 250, 'progress_partner1': 0, 'progress_partner2': 0, 'is_open': True}
Not Found: /pomo/timer/
Exception while resolving variable 'player_state_json' in template 'pomo/map.html'.
Traceback (most recent call last):
  File "/home/timoh/projects/master-o-meter/.venv/lib/python3.9/site-packages/django/template/base.py", line 880, in _resolve_lookup
    current = current[bit]
  File "/home/timoh/projects/master-o-meter/.venv/lib/python3.9/site-packages/django/template/context.py", line 83, in __getitem__
    raise KeyError(key)
KeyError: 'player_state_json'

During handling of the above exception, another exception occurred:

Traceback (most recent call last):
  File "/home/timoh/projects/master-o-meter/.venv/lib/python3.9/site-packages/django/template/base.py", line 886, in _resolve_lookup
    if isinstance(current, BaseContext) and getattr(
AttributeError: type object 'RequestContext' has no attribute 'player_state_json'

During handling of the above exception, another exception occurred:

Traceback (most recent call last):
  File "/home/timoh/projects/master-o-meter/.venv/lib/python3.9/site-packages/django/template/base.py", line 896, in _resolve_lookup
    current = current[int(bit)]
ValueError: invalid literal for int() with base 10: 'player_state_json'

During handling of the above exception, another exception occurred:

Traceback (most recent call last):
  File "/home/timoh/projects/master-o-meter/.venv/lib/python3.9/site-packages/django/template/base.py", line 903, in _resolve_lookup
    raise VariableDoesNotExist(
django.template.base.VariableDoesNotExist: Failed lookup for key [player_state_json] in [{'True': True, 'False': False, 'None': None}, {'csrf_token': <SimpleLazyObject: '1gBvPBPDRTXy8fAA32thx89oF9z6ZWdLRG1ENoG09gQpBm26bBNMN9lyCelXUKtM'>, 'request': <WSGIRequest: GET '/pomo/'>, 'user': <SimpleLazyObject: <User: developer>>, 'perms': PermWrapper(<SimpleLazyObject: <User: developer>>), 'messages': <FallbackStorage: request=<WSGIRequest: GET '/pomo/'>>, 'DEFAULT_MESSAGE_LEVELS': {'DEBUG': 10, 'INFO': 20, 'SUCCESS': 25, 'WARNING': 30, 'ERROR': 40}}, {}, {'total_pomos_alltime': 25, 'total_pomodoros_today': 0, 'streak': 3, 'is_developer': True, 'username': 'developer'}]
Exception while resolving variable 'location_states_json' in template 'pomo/map.html'.
Traceback (most recent call last):
  File "/home/timoh/projects/master-o-meter/.venv/lib/python3.9/site-packages/django/template/base.py", line 880, in _resolve_lookup
    current = current[bit]
  File "/home/timoh/projects/master-o-meter/.venv/lib/python3.9/site-packages/django/template/context.py", line 83, in __getitem__
    raise KeyError(key)
KeyError: 'location_states_json'

During handling of the above exception, another exception occurred:

Traceback (most recent call last):
  File "/home/timoh/projects/master-o-meter/.venv/lib/python3.9/site-packages/django/template/base.py", line 886, in _resolve_lookup
    if isinstance(current, BaseContext) and getattr(
AttributeError: type object 'RequestContext' has no attribute 'location_states_json'

During handling of the above exception, another exception occurred:

Traceback (most recent call last):
  File "/home/timoh/projects/master-o-meter/.venv/lib/python3.9/site-packages/django/template/base.py", line 896, in _resolve_lookup
    current = current[int(bit)]
ValueError: invalid literal for int() with base 10: 'location_states_json'

During handling of the above exception, another exception occurred:

Traceback (most recent call last):
  File "/home/timoh/projects/master-o-meter/.venv/lib/python3.9/site-packages/django/template/base.py", line 903, in _resolve_lookup
    raise VariableDoesNotExist(
django.template.base.VariableDoesNotExist: Failed lookup for key [location_states_json] in [{'True': True, 'False': False, 'None': None}, {'csrf_token': <SimpleLazyObject: '1gBvPBPDRTXy8fAA32thx89oF9z6ZWdLRG1ENoG09gQpBm26bBNMN9lyCelXUKtM'>, 'request': <WSGIRequest: GET '/pomo/'>, 'user': <SimpleLazyObject: <User: developer>>, 'perms': PermWrapper(<SimpleLazyObject: <User: developer>>), 'messages': <FallbackStorage: request=<WSGIRequest: GET '/pomo/'>>, 'DEFAULT_MESSAGE_LEVELS': {'DEBUG': 10, 'INFO': 20, 'SUCCESS': 25, 'WARNING': 30, 'ERROR': 40}}, {}, {'total_pomos_alltime': 25, 'total_pomodoros_today': 0, 'streak': 3, 'is_developer': True, 'username': 'developer'}]
Exception while resolving variable 'player_state_json' in template 'pomo/map.html'.
Traceback (most recent call last):
  File "/home/timoh/projects/master-o-meter/.venv/lib/python3.9/site-packages/django/template/base.py", line 880, in _resolve_lookup
    current = current[bit]
  File "/home/timoh/projects/master-o-meter/.venv/lib/python3.9/site-packages/django/template/context.py", line 83, in __getitem__
    raise KeyError(key)
KeyError: 'player_state_json'

During handling of the above exception, another exception occurred:

Traceback (most recent call last):
  File "/home/timoh/projects/master-o-meter/.venv/lib/python3.9/site-packages/django/template/base.py", line 886, in _resolve_lookup
    if isinstance(current, BaseContext) and getattr(
AttributeError: type object 'RequestContext' has no attribute 'player_state_json'

During handling of the above exception, another exception occurred:

Traceback (most recent call last):
  File "/home/timoh/projects/master-o-meter/.venv/lib/python3.9/site-packages/django/template/base.py", line 896, in _resolve_lookup
    current = current[int(bit)]
ValueError: invalid literal for int() with base 10: 'player_state_json'

During handling of the above exception, another exception occurred:

Traceback (most recent call last):
  File "/home/timoh/projects/master-o-meter/.venv/lib/python3.9/site-packages/django/template/base.py", line 903, in _resolve_lookup
    raise VariableDoesNotExist(
django.template.base.VariableDoesNotExist: Failed lookup for key [player_state_json] in [{'True': True, 'False': False, 'None': None}, {'csrf_token': <SimpleLazyObject: 'sB6wdm0uEJC91TOIdKgzwGNbj1RZsfs4P2rASsUDBGRgBi8de1VUBTHNAK58XA04'>, 'request': <WSGIRequest: GET '/pomo/'>, 'user': <SimpleLazyObject: <User: timoh>>, 'perms': PermWrapper(<SimpleLazyObject: <User: timoh>>), 'messages': <FallbackStorage: request=<WSGIRequest: GET '/pomo/'>>, 'DEFAULT_MESSAGE_LEVELS': {'DEBUG': 10, 'INFO': 20, 'SUCCESS': 25, 'WARNING': 30, 'ERROR': 40}}, {}, {'total_pomos_alltime': 94, 'total_pomodoros_today': 0, 'streak': 0, 'is_developer': False, 'username': 'timoh'}]
Exception while resolving variable 'location_states_json' in template 'pomo/map.html'.
Traceback (most recent call last):
  File "/home/timoh/projects/master-o-meter/.venv/lib/python3.9/site-packages/django/template/base.py", line 880, in _resolve_lookup
    current = current[bit]
  File "/home/timoh/projects/master-o-meter/.venv/lib/python3.9/site-packages/django/template/context.py", line 83, in __getitem__
    raise KeyError(key)
KeyError: 'location_states_json'

During handling of the above exception, another exception occurred:

Traceback (most recent call last):
  File "/home/timoh/projects/master-o-meter/.venv/lib/python3.9/site-packages/django/template/base.py", line 886, in _resolve_lookup
    if isinstance(current, BaseContext) and getattr(
AttributeError: type object 'RequestContext' has no attribute 'location_states_json'

During handling of the above exception, another exception occurred:

Traceback (most recent call last):
  File "/home/timoh/projects/master-o-meter/.venv/lib/python3.9/site-packages/django/template/base.py", line 896, in _resolve_lookup
    current = current[int(bit)]
ValueError: invalid literal for int() with base 10: 'location_states_json'

During handling of the above exception, another exception occurred:

Traceback (most recent call last):
  File "/home/timoh/projects/master-o-meter/.venv/lib/python3.9/site-packages/django/template/base.py", line 903, in _resolve_lookup
    raise VariableDoesNotExist(
django.template.base.VariableDoesNotExist: Failed lookup for key [location_states_json] in [{'True': True, 'False': False, 'None': None}, {'csrf_token': <SimpleLazyObject: 'sB6wdm0uEJC91TOIdKgzwGNbj1RZsfs4P2rASsUDBGRgBi8de1VUBTHNAK58XA04'>, 'request': <WSGIRequest: GET '/pomo/'>, 'user': <SimpleLazyObject: <User: timoh>>, 'perms': PermWrapper(<SimpleLazyObject: <User: timoh>>), 'messages': <FallbackStorage: request=<WSGIRequest: GET '/pomo/'>>, 'DEFAULT_MESSAGE_LEVELS': {'DEBUG': 10, 'INFO': 20, 'SUCCESS': 25, 'WARNING': 30, 'ERROR': 40}}, {}, {'total_pomos_alltime': 94, 'total_pomodoros_today': 0, 'streak': 0, 'is_developer': False, 'username': 'timoh'}]
Exception while resolving variable 'balance_error' in template 'pomo/trophy_room.html'.
Traceback (most recent call last):
  File "/home/timoh/projects/master-o-meter/.venv/lib/python3.9/site-packages/django/template/base.py", line 880, in _resolve_lookup
    current = current[bit]
  File "/home/timoh/projects/master-o-meter/.venv/lib/python3.9/site-packages/django/template/context.py", line 83, in __getitem__
    raise KeyError(key)
KeyError: 'balance_error'

During handling of the above exception, another exception occurred:

Traceback (most recent call last):
  File "/home/timoh/projects/master-o-meter/.venv/lib/python3.9/site-packages/django/template/base.py", line 886, in _resolve_lookup
    if isinstance(current, BaseContext) and getattr(
AttributeError: type object 'RequestContext' has no attribute 'balance_error'

During handling of the above exception, another exception occurred:

Traceback (most recent call last):
  File "/home/timoh/projects/master-o-meter/.venv/lib/python3.9/site-packages/django/template/base.py", line 896, in _resolve_lookup
    current = current[int(bit)]
ValueError: invalid literal for int() with base 10: 'balance_error'

During handling of the above exception, another exception occurred:

Traceback (most recent call last):
  File "/home/timoh/projects/master-o-meter/.venv/lib/python3.9/site-packages/django/template/base.py", line 903, in _resolve_lookup
    raise VariableDoesNotExist(
django.template.base.VariableDoesNotExist: Failed lookup for key [balance_error] in [{'True': True, 'False': False, 'None': None}, {'csrf_token': <SimpleLazyObject: '2oOkehQmYiswK7O1o5aalPtaVXr6xuRIpP9oTnKvVfHDkw8wpmPvq2nMcGFf2PpI'>, 'request': <WSGIRequest: GET '/pomo/trophy-room/'>, 'user': <SimpleLazyObject: <User: timoh>>, 'perms': PermWrapper(<SimpleLazyObject: <User: timoh>>), 'messages': <FallbackStorage: request=<WSGIRequest: GET '/pomo/trophy-room/'>>, 'DEFAULT_MESSAGE_LEVELS': {'DEBUG': 10, 'INFO': 20, 'SUCCESS': 25, 'WARNING': 30, 'ERROR': 40}}, {}, {'total_pomos_alltime': 95, 'total_pomodoros_today': 1, 'streak': 1, 'study_hours_last_seven_days': [0.5, 0.0, 0.0, 0.0, 0.0, 0.0, 0.0], 'balance': <Balance: timoh's Points>, 'unclaimed_rewards': <QuerySet [<Reward: Eat out>, <Reward: ??? episode>]>, 'claimed_rewards': <QuerySet [<Reward: test>]>}]
Not Found: /favicon.ico
Exception while resolving variable 'player_state_json' in template 'pomo/map.html'.
Traceback (most recent call last):
  File "/home/timoh/projects/master-o-meter/.venv/lib/python3.9/site-packages/django/template/base.py", line 880, in _resolve_lookup
    current = current[bit]
  File "/home/timoh/projects/master-o-meter/.venv/lib/python3.9/site-packages/django/template/context.py", line 83, in __getitem__
    raise KeyError(key)
KeyError: 'player_state_json'

During handling of the above exception, another exception occurred:

Traceback (most recent call last):
  File "/home/timoh/projects/master-o-meter/.venv/lib/python3.9/site-packages/django/template/base.py", line 886, in _resolve_lookup
    if isinstance(current, BaseContext) and getattr(
AttributeError: type object 'RequestContext' has no attribute 'player_state_json'

During handling of the above exception, another exception occurred:

Traceback (most recent call last):
  File "/home/timoh/projects/master-o-meter/.venv/lib/python3.9/site-packages/django/template/base.py", line 896, in _resolve_lookup
    current = current[int(bit)]
ValueError: invalid literal for int() with base 10: 'player_state_json'

During handling of the above exception, another exception occurred:

Traceback (most recent call last):
  File "/home/timoh/projects/master-o-meter/.venv/lib/python3.9/site-packages/django/template/base.py", line 903, in _resolve_lookup
    raise VariableDoesNotExist(
django.template.base.VariableDoesNotExist: Failed lookup for key [player_state_json] in [{'True': True, 'False': False, 'None': None}, {'csrf_token': <SimpleLazyObject: 'pKxqxtlehKrdTvHUiwFIvck8Yv7qCypsMbSuczfneHGktU1pjNk3ApeKfelz7TXs'>, 'request': <WSGIRequest: GET '/pomo/'>, 'user': <SimpleLazyObject: <User: timoh>>, 'perms': PermWrapper(<SimpleLazyObject: <User: timoh>>), 'messages': <FallbackStorage: request=<WSGIRequest: GET '/pomo/'>>, 'DEFAULT_MESSAGE_LEVELS': {'DEBUG': 10, 'INFO': 20, 'SUCCESS': 25, 'WARNING': 30, 'ERROR': 40}}, {}, {'total_pomos_alltime': 96, 'total_pomodoros_today': 2, 'streak': 1, 'is_developer': False, 'username': 'timoh'}]
Exception while resolving variable 'location_states_json' in template 'pomo/map.html'.
Traceback (most recent call last):
  File "/home/timoh/projects/master-o-meter/.venv/lib/python3.9/site-packages/django/template/base.py", line 880, in _resolve_lookup
    current = current[bit]
  File "/home/timoh/projects/master-o-meter/.venv/lib/python3.9/site-packages/django/template/context.py", line 83, in __getitem__
    raise KeyError(key)
KeyError: 'location_states_json'

During handling of the above exception, another exception occurred:

Traceback (most recent call last):
  File "/home/timoh/projects/master-o-meter/.venv/lib/python3.9/site-packages/django/template/base.py", line 886, in _resolve_lookup
    if isinstance(current, BaseContext) and getattr(
AttributeError: type object 'RequestContext' has no attribute 'location_states_json'

During handling of the above exception, another exception occurred:

Traceback (most recent call last):
  File "/home/timoh/projects/master-o-meter/.venv/lib/python3.9/site-packages/django/template/base.py", line 896, in _resolve_lookup
    current = current[int(bit)]
ValueError: invalid literal for int() with base 10: 'location_states_json'

During handling of the above exception, another exception occurred:

Traceback (most recent call last):
  File "/home/timoh/projects/master-o-meter/.venv/lib/python3.9/site-packages/django/template/base.py", line 903, in _resolve_lookup
    raise VariableDoesNotExist(
django.template.base.VariableDoesNotExist: Failed lookup for key [location_states_json] in [{'True': True, 'False': False, 'None': None}, {'csrf_token': <SimpleLazyObject: 'pKxqxtlehKrdTvHUiwFIvck8Yv7qCypsMbSuczfneHGktU1pjNk3ApeKfelz7TXs'>, 'request': <WSGIRequest: GET '/pomo/'>, 'user': <SimpleLazyObject: <User: timoh>>, 'perms': PermWrapper(<SimpleLazyObject: <User: timoh>>), 'messages': <FallbackStorage: request=<WSGIRequest: GET '/pomo/'>>, 'DEFAULT_MESSAGE_LEVELS': {'DEBUG': 10, 'INFO': 20, 'SUCCESS': 25, 'WARNING': 30, 'ERROR': 40}}, {}, {'total_pomos_alltime': 96, 'total_pomodoros_today': 2, 'streak': 1, 'is_developer': False, 'username': 'timoh'}]
Exception while resolving variable 'balance_error' in template 'pomo/trophy_room.html'.
Traceback (most recent call last):
  File "/home/timoh/projects/master-o-meter/.venv/lib/python3.9/site-packages/django/template/base.py", line 880, in _resolve_lookup
    current = current[bit]
  File "/home/timoh/projects/master-o-meter/.venv/lib/python3.9/site-packages/django/template/context.py", line 83, in __getitem__
    raise KeyError(key)
KeyError: 'balance_error'

During handling of the above exception, another exception occurred:

Traceback (most recent call last):
  File "/home/timoh/projects/master-o-meter/.venv/lib/python3.9/site-packages/django/template/base.py", line 886, in _resolve_lookup
    if isinstance(current, BaseContext) and getattr(
AttributeError: type object 'RequestContext' has no attribute 'balance_error'

During handling of the above exception, another exception occurred:

Traceback (most recent call last):
  File "/home/timoh/projects/master-o-meter/.venv/lib/python3.9/site-packages/django/template/base.py", line 896, in _resolve_lookup
    current = current[int(bit)]
ValueError: invalid literal for int() with base 10: 'balance_error'

During handling of the above exception, another exception occurred:

Traceback (most recent call last):
  File "/home/timoh/projects/master-o-meter/.venv/lib/python3.9/site-packages/django/template/base.py", line 903, in _resolve_lookup
    raise VariableDoesNotExist(
django.template.base.VariableDoesNotExist: Failed lookup for key [balance_error] in [{'True': True, 'False': False, 'None': None}, {'csrf_token': <SimpleLazyObject: 'F0kwWIvS24yzVVVXUOoDgdnfKRw7FrDB2rFABOp1Z1NGvkfsV53YlqhR1AKgaMbB'>, 'request': <WSGIRequest: GET '/pomo/trophy-room/'>, 'user': <SimpleLazyObject: <User: timoh>>, 'perms': PermWrapper(<SimpleLazyObject: <User: timoh>>), 'messages': <FallbackStorage: request=<WSGIRequest: GET '/pomo/trophy-room/'>>, 'DEFAULT_MESSAGE_LEVELS': {'DEBUG': 10, 'INFO': 20, 'SUCCESS': 25, 'WARNING': 30, 'ERROR': 40}}, {}, {'total_pomos_alltime': 96, 'total_pomodoros_today': 2, 'streak': 1, 'study_hours_last_seven_days': [1.0, 0.0, 0.0, 0.0, 0.0, 0.0, 0.0], 'balance': <Balance: timoh's Points>, 'unclaimed_rewards': <QuerySet [<Reward: Eat out>, <Reward: ??? episode>]>, 'claimed_rewards': <QuerySet [<Reward: test>]>}]
Not Found: /favicon.ico
Exception while resolving variable 'player_state_json' in template 'pomo/map.html'.
Traceback (most recent call last):
  File "/home/timoh/projects/master-o-meter/.venv/lib/python3.9/site-packages/django/template/base.py", line 880, in _resolve_lookup
    current = current[bit]
  File "/home/timoh/projects/master-o-meter/.venv/lib/python3.9/site-packages/django/template/context.py", line 83, in __getitem__
    raise KeyError(key)
KeyError: 'player_state_json'

During handling of the above exception, another exception occurred:

Traceback (most recent call last):
  File "/home/timoh/projects/master-o-meter/.venv/lib/python3.9/site-packages/django/template/base.py", line 886, in _resolve_lookup
    if isinstance(current, BaseContext) and getattr(
AttributeError: type object 'RequestContext' has no attribute 'player_state_json'

During handling of the above exception, another exception occurred:

Traceback (most recent call last):
  File "/home/timoh/projects/master-o-meter/.venv/lib/python3.9/site-packages/django/template/base.py", line 896, in _resolve_lookup
    current = current[int(bit)]
ValueError: invalid literal for int() with base 10: 'player_state_json'

During handling of the above exception, another exception occurred:

Traceback (most recent call last):
  File "/home/timoh/projects/master-o-meter/.venv/lib/python3.9/site-packages/django/template/base.py", line 903, in _resolve_lookup
    raise VariableDoesNotExist(
django.template.base.VariableDoesNotExist: Failed lookup for key [player_state_json] in [{'True': True, 'False': False, 'None': None}, {'csrf_token': <SimpleLazyObject: 'mbd9D32KQcvJK5NfZkbabPzIt1PRVOC2sSqj0culVG7MZoyCiH96hy4LNafQcAI3'>, 'request': <WSGIRequest: GET '/pomo/'>, 'user': <SimpleLazyObject: <User: developer>>, 'perms': PermWrapper(<SimpleLazyObject: <User: developer>>), 'messages': <FallbackStorage: request=<WSGIRequest: GET '/pomo/'>>, 'DEFAULT_MESSAGE_LEVELS': {'DEBUG': 10, 'INFO': 20, 'SUCCESS': 25, 'WARNING': 30, 'ERROR': 40}}, {}, {'total_pomos_alltime': 25, 'total_pomodoros_today': 0, 'streak': 3, 'is_developer': True, 'username': 'developer'}]
Exception while resolving variable 'location_states_json' in template 'pomo/map.html'.
Traceback (most recent call last):
  File "/home/timoh/projects/master-o-meter/.venv/lib/python3.9/site-packages/django/template/base.py", line 880, in _resolve_lookup
    current = current[bit]
  File "/home/timoh/projects/master-o-meter/.venv/lib/python3.9/site-packages/django/template/context.py", line 83, in __getitem__
    raise KeyError(key)
KeyError: 'location_states_json'

During handling of the above exception, another exception occurred:

Traceback (most recent call last):
  File "/home/timoh/projects/master-o-meter/.venv/lib/python3.9/site-packages/django/template/base.py", line 886, in _resolve_lookup
    if isinstance(current, BaseContext) and getattr(
AttributeError: type object 'RequestContext' has no attribute 'location_states_json'

During handling of the above exception, another exception occurred:

Traceback (most recent call last):
  File "/home/timoh/projects/master-o-meter/.venv/lib/python3.9/site-packages/django/template/base.py", line 896, in _resolve_lookup
    current = current[int(bit)]
ValueError: invalid literal for int() with base 10: 'location_states_json'

During handling of the above exception, another exception occurred:

Traceback (most recent call last):
  File "/home/timoh/projects/master-o-meter/.venv/lib/python3.9/site-packages/django/template/base.py", line 903, in _resolve_lookup
    raise VariableDoesNotExist(
django.template.base.VariableDoesNotExist: Failed lookup for key [location_states_json] in [{'True': True, 'False': False, 'None': None}, {'csrf_token': <SimpleLazyObject: 'mbd9D32KQcvJK5NfZkbabPzIt1PRVOC2sSqj0culVG7MZoyCiH96hy4LNafQcAI3'>, 'request': <WSGIRequest: GET '/pomo/'>, 'user': <SimpleLazyObject: <User: developer>>, 'perms': PermWrapper(<SimpleLazyObject: <User: developer>>), 'messages': <FallbackStorage: request=<WSGIRequest: GET '/pomo/'>>, 'DEFAULT_MESSAGE_LEVELS': {'DEBUG': 10, 'INFO': 20, 'SUCCESS': 25, 'WARNING': 30, 'ERROR': 40}}, {}, {'total_pomos_alltime': 25, 'total_pomodoros_today': 0, 'streak': 3, 'is_developer': True, 'username': 'developer'}]
Exception while resolving variable 'partner1_progress' in template 'pomo/common_rooms.html'.
Traceback (most recent call last):
  File "/home/timoh/projects/master-o-meter/.venv/lib/python3.9/site-packages/django/template/base.py", line 880, in _resolve_lookup
    current = current[bit]
KeyError: 'partner1_progress'

During handling of the above exception, another exception occurred:

Traceback (most recent call last):
  File "/home/timoh/projects/master-o-meter/.venv/lib/python3.9/site-packages/django/template/base.py", line 890, in _resolve_lookup
    current = getattr(current, bit)
AttributeError: 'dict' object has no attribute 'partner1_progress'

During handling of the above exception, another exception occurred:

Traceback (most recent call last):
  File "/home/timoh/projects/master-o-meter/.venv/lib/python3.9/site-packages/django/template/base.py", line 896, in _resolve_lookup
    current = current[int(bit)]
ValueError: invalid literal for int() with base 10: 'partner1_progress'

During handling of the above exception, another exception occurred:

Traceback (most recent call last):
  File "/home/timoh/projects/master-o-meter/.venv/lib/python3.9/site-packages/django/template/base.py", line 903, in _resolve_lookup
    raise VariableDoesNotExist(
django.template.base.VariableDoesNotExist: Failed lookup for key [partner1_progress] in {'partner1': 'developer2', 'partner2': 'developer', 'start_time': datetime.datetime(2025, 1, 5, 15, 52, 49, 883013, tzinfo=datetime.timezone.utc), 'end_time': datetime.datetime(2025, 1, 8, 15, 52, 49, 882451, tzinfo=datetime.timezone.utc), 'size': 250, 'progress_partner1': 0, 'progress_partner2': 0, 'is_open': True}
Exception while resolving variable 'partner2_progress' in template 'pomo/common_rooms.html'.
Traceback (most recent call last):
  File "/home/timoh/projects/master-o-meter/.venv/lib/python3.9/site-packages/django/template/base.py", line 880, in _resolve_lookup
    current = current[bit]
KeyError: 'partner2_progress'

During handling of the above exception, another exception occurred:

Traceback (most recent call last):
  File "/home/timoh/projects/master-o-meter/.venv/lib/python3.9/site-packages/django/template/base.py", line 890, in _resolve_lookup
    current = getattr(current, bit)
AttributeError: 'dict' object has no attribute 'partner2_progress'

During handling of the above exception, another exception occurred:

Traceback (most recent call last):
  File "/home/timoh/projects/master-o-meter/.venv/lib/python3.9/site-packages/django/template/base.py", line 896, in _resolve_lookup
    current = current[int(bit)]
ValueError: invalid literal for int() with base 10: 'partner2_progress'

During handling of the above exception, another exception occurred:

Traceback (most recent call last):
  File "/home/timoh/projects/master-o-meter/.venv/lib/python3.9/site-packages/django/template/base.py", line 903, in _resolve_lookup
    raise VariableDoesNotExist(
django.template.base.VariableDoesNotExist: Failed lookup for key [partner2_progress] in {'partner1': 'developer2', 'partner2': 'developer', 'start_time': datetime.datetime(2025, 1, 5, 15, 52, 49, 883013, tzinfo=datetime.timezone.utc), 'end_time': datetime.datetime(2025, 1, 8, 15, 52, 49, 882451, tzinfo=datetime.timezone.utc), 'size': 250, 'progress_partner1': 0, 'progress_partner2': 0, 'is_open': True}
Exception while resolving variable 'is_completed' in template 'pomo/common_rooms.html'.
Traceback (most recent call last):
  File "/home/timoh/projects/master-o-meter/.venv/lib/python3.9/site-packages/django/template/base.py", line 880, in _resolve_lookup
    current = current[bit]
KeyError: 'is_completed'

During handling of the above exception, another exception occurred:

Traceback (most recent call last):
  File "/home/timoh/projects/master-o-meter/.venv/lib/python3.9/site-packages/django/template/base.py", line 890, in _resolve_lookup
    current = getattr(current, bit)
AttributeError: 'dict' object has no attribute 'is_completed'

During handling of the above exception, another exception occurred:

Traceback (most recent call last):
  File "/home/timoh/projects/master-o-meter/.venv/lib/python3.9/site-packages/django/template/base.py", line 896, in _resolve_lookup
    current = current[int(bit)]
ValueError: invalid literal for int() with base 10: 'is_completed'

During handling of the above exception, another exception occurred:

Traceback (most recent call last):
  File "/home/timoh/projects/master-o-meter/.venv/lib/python3.9/site-packages/django/template/base.py", line 903, in _resolve_lookup
    raise VariableDoesNotExist(
django.template.base.VariableDoesNotExist: Failed lookup for key [is_completed] in {'partner1': 'developer2', 'partner2': 'developer', 'start_time': datetime.datetime(2025, 1, 5, 15, 52, 49, 883013, tzinfo=datetime.timezone.utc), 'end_time': datetime.datetime(2025, 1, 8, 15, 52, 49, 882451, tzinfo=datetime.timezone.utc), 'size': 250, 'progress_partner1': 0, 'progress_partner2': 0, 'is_open': True}
Exception while resolving variable 'partner1_progress' in template 'pomo/common_rooms.html'.
Traceback (most recent call last):
  File "/home/timoh/projects/master-o-meter/.venv/lib/python3.9/site-packages/django/template/base.py", line 880, in _resolve_lookup
    current = current[bit]
KeyError: 'partner1_progress'

During handling of the above exception, another exception occurred:

Traceback (most recent call last):
  File "/home/timoh/projects/master-o-meter/.venv/lib/python3.9/site-packages/django/template/base.py", line 890, in _resolve_lookup
    current = getattr(current, bit)
AttributeError: 'dict' object has no attribute 'partner1_progress'

During handling of the above exception, another exception occurred:

Traceback (most recent call last):
  File "/home/timoh/projects/master-o-meter/.venv/lib/python3.9/site-packages/django/template/base.py", line 896, in _resolve_lookup
    current = current[int(bit)]
ValueError: invalid literal for int() with base 10: 'partner1_progress'

During handling of the above exception, another exception occurred:

Traceback (most recent call last):
  File "/home/timoh/projects/master-o-meter/.venv/lib/python3.9/site-packages/django/template/base.py", line 903, in _resolve_lookup
    raise VariableDoesNotExist(
django.template.base.VariableDoesNotExist: Failed lookup for key [partner1_progress] in {'partner1': 'developer2', 'partner2': 'developer', 'start_time': datetime.datetime(2025, 1, 5, 15, 52, 49, 883013, tzinfo=datetime.timezone.utc), 'end_time': datetime.datetime(2025, 1, 8, 15, 52, 49, 882451, tzinfo=datetime.timezone.utc), 'size': 250, 'progress_partner1': 0, 'progress_partner2': 0, 'is_open': True}
Exception while resolving variable 'partner2_progress' in template 'pomo/common_rooms.html'.
Traceback (most recent call last):
  File "/home/timoh/projects/master-o-meter/.venv/lib/python3.9/site-packages/django/template/base.py", line 880, in _resolve_lookup
    current = current[bit]
KeyError: 'partner2_progress'

During handling of the above exception, another exception occurred:

Traceback (most recent call last):
  File "/home/timoh/projects/master-o-meter/.venv/lib/python3.9/site-packages/django/template/base.py", line 890, in _resolve_lookup
    current = getattr(current, bit)
AttributeError: 'dict' object has no attribute 'partner2_progress'

During handling of the above exception, another exception occurred:

Traceback (most recent call last):
  File "/home/timoh/projects/master-o-meter/.venv/lib/python3.9/site-packages/django/template/base.py", line 896, in _resolve_lookup
    current = current[int(bit)]
ValueError: invalid literal for int() with base 10: 'partner2_progress'

During handling of the above exception, another exception occurred:

Traceback (most recent call last):
  File "/home/timoh/projects/master-o-meter/.venv/lib/python3.9/site-packages/django/template/base.py", line 903, in _resolve_lookup
    raise VariableDoesNotExist(
django.template.base.VariableDoesNotExist: Failed lookup for key [partner2_progress] in {'partner1': 'developer2', 'partner2': 'developer', 'start_time': datetime.datetime(2025, 1, 5, 15, 52, 49, 883013, tzinfo=datetime.timezone.utc), 'end_time': datetime.datetime(2025, 1, 8, 15, 52, 49, 882451, tzinfo=datetime.timezone.utc), 'size': 250, 'progress_partner1': 0, 'progress_partner2': 0, 'is_open': True}
Exception while resolving variable 'is_completed' in template 'pomo/common_rooms.html'.
Traceback (most recent call last):
  File "/home/timoh/projects/master-o-meter/.venv/lib/python3.9/site-packages/django/template/base.py", line 880, in _resolve_lookup
    current = current[bit]
KeyError: 'is_completed'

During handling of the above exception, another exception occurred:

Traceback (most recent call last):
  File "/home/timoh/projects/master-o-meter/.venv/lib/python3.9/site-packages/django/template/base.py", line 890, in _resolve_lookup
    current = getattr(current, bit)
AttributeError: 'dict' object has no attribute 'is_completed'

During handling of the above exception, another exception occurred:

Traceback (most recent call last):
  File "/home/timoh/projects/master-o-meter/.venv/lib/python3.9/site-packages/django/template/base.py", line 896, in _resolve_lookup
    current = current[int(bit)]
ValueError: invalid literal for int() with base 10: 'is_completed'

During handling of the above exception, another exception occurred:

Traceback (most recent call last):
  File "/home/timoh/projects/master-o-meter/.venv/lib/python3.9/site-packages/django/template/base.py", line 903, in _resolve_lookup
    raise VariableDoesNotExist(
django.template.base.VariableDoesNotExist: Failed lookup for key [is_completed] in {'partner1': 'developer2', 'partner2': 'developer', 'start_time': datetime.datetime(2025, 1, 5, 15, 52, 49, 883013, tzinfo=datetime.timezone.utc), 'end_time': datetime.datetime(2025, 1, 8, 15, 52, 49, 882451, tzinfo=datetime.timezone.utc), 'size': 250, 'progress_partner1': 0, 'progress_partner2': 0, 'is_open': True}
Exception while resolving variable 'id' in template 'pomo/common_rooms.html'.
Traceback (most recent call last):
  File "/home/timoh/projects/master-o-meter/.venv/lib/python3.9/site-packages/django/template/base.py", line 880, in _resolve_lookup
    current = current[bit]
KeyError: 'id'

During handling of the above exception, another exception occurred:

Traceback (most recent call last):
  File "/home/timoh/projects/master-o-meter/.venv/lib/python3.9/site-packages/django/template/base.py", line 890, in _resolve_lookup
    current = getattr(current, bit)
AttributeError: 'dict' object has no attribute 'id'

During handling of the above exception, another exception occurred:

Traceback (most recent call last):
  File "/home/timoh/projects/master-o-meter/.venv/lib/python3.9/site-packages/django/template/base.py", line 896, in _resolve_lookup
    current = current[int(bit)]
ValueError: invalid literal for int() with base 10: 'id'

During handling of the above exception, another exception occurred:

Traceback (most recent call last):
  File "/home/timoh/projects/master-o-meter/.venv/lib/python3.9/site-packages/django/template/base.py", line 903, in _resolve_lookup
    raise VariableDoesNotExist(
django.template.base.VariableDoesNotExist: Failed lookup for key [id] in {'username': 'timoh', 'streak': 1, 'pomodoros_today': 2}
Internal Server Error: /pomo/common_rooms/
Traceback (most recent call last):
  File "/home/timoh/projects/master-o-meter/.venv/lib/python3.9/site-packages/django/core/handlers/exception.py", line 55, in inner
    response = get_response(request)
  File "/home/timoh/projects/master-o-meter/.venv/lib/python3.9/site-packages/django/core/handlers/base.py", line 197, in _get_response
    response = wrapped_callback(request, *callback_args, **callback_kwargs)
  File "/home/timoh/projects/master-o-meter/.venv/lib/python3.9/site-packages/django/contrib/auth/decorators.py", line 23, in _wrapper_view
    return view_func(request, *args, **kwargs)
  File "/home/timoh/projects/master-o-meter/webapp/pomo/views.py", line 124, in common_rooms
    return render(request, 'pomo/common_rooms.html', {
  File "/home/timoh/projects/master-o-meter/.venv/lib/python3.9/site-packages/django/shortcuts.py", line 24, in render
    content = loader.render_to_string(template_name, context, request, using=using)
  File "/home/timoh/projects/master-o-meter/.venv/lib/python3.9/site-packages/django/template/loader.py", line 62, in render_to_string
    return template.render(context, request)
  File "/home/timoh/projects/master-o-meter/.venv/lib/python3.9/site-packages/django/template/backends/django.py", line 61, in render
    return self.template.render(context)
  File "/home/timoh/projects/master-o-meter/.venv/lib/python3.9/site-packages/django/template/base.py", line 175, in render
    return self._render(context)
  File "/home/timoh/projects/master-o-meter/.venv/lib/python3.9/site-packages/django/template/base.py", line 167, in _render
    return self.nodelist.render(context)
  File "/home/timoh/projects/master-o-meter/.venv/lib/python3.9/site-packages/django/template/base.py", line 1005, in render
    return SafeString("".join([node.render_annotated(context) for node in self]))
  File "/home/timoh/projects/master-o-meter/.venv/lib/python3.9/site-packages/django/template/base.py", line 1005, in <listcomp>
    return SafeString("".join([node.render_annotated(context) for node in self]))
  File "/home/timoh/projects/master-o-meter/.venv/lib/python3.9/site-packages/django/template/base.py", line 966, in render_annotated
    return self.render(context)
  File "/home/timoh/projects/master-o-meter/.venv/lib/python3.9/site-packages/django/template/defaulttags.py", line 238, in render
    nodelist.append(node.render_annotated(context))
  File "/home/timoh/projects/master-o-meter/.venv/lib/python3.9/site-packages/django/template/base.py", line 966, in render_annotated
    return self.render(context)
  File "/home/timoh/projects/master-o-meter/.venv/lib/python3.9/site-packages/django/template/defaulttags.py", line 471, in render
    url = reverse(view_name, args=args, kwargs=kwargs, current_app=current_app)
  File "/home/timoh/projects/master-o-meter/.venv/lib/python3.9/site-packages/django/urls/base.py", line 88, in reverse
    return resolver._reverse_with_prefix(view, prefix, *args, **kwargs)
  File "/home/timoh/projects/master-o-meter/.venv/lib/python3.9/site-packages/django/urls/resolvers.py", line 828, in _reverse_with_prefix
    raise NoReverseMatch(msg)
django.urls.exceptions.NoReverseMatch: Reverse for 'send_partner_quest_request' with arguments '('',)' not found. 1 pattern(s) tried: ['pomo/send_partner_quest_request/(?P<user_id>[0-9]+)/\\Z']
Exception while resolving variable 'partner1_progress' in template 'pomo/common_rooms.html'.
Traceback (most recent call last):
  File "/home/timoh/projects/master-o-meter/.venv/lib/python3.9/site-packages/django/template/base.py", line 880, in _resolve_lookup
    current = current[bit]
KeyError: 'partner1_progress'

During handling of the above exception, another exception occurred:

Traceback (most recent call last):
  File "/home/timoh/projects/master-o-meter/.venv/lib/python3.9/site-packages/django/template/base.py", line 890, in _resolve_lookup
    current = getattr(current, bit)
AttributeError: 'dict' object has no attribute 'partner1_progress'

During handling of the above exception, another exception occurred:

Traceback (most recent call last):
  File "/home/timoh/projects/master-o-meter/.venv/lib/python3.9/site-packages/django/template/base.py", line 896, in _resolve_lookup
    current = current[int(bit)]
ValueError: invalid literal for int() with base 10: 'partner1_progress'

During handling of the above exception, another exception occurred:

Traceback (most recent call last):
  File "/home/timoh/projects/master-o-meter/.venv/lib/python3.9/site-packages/django/template/base.py", line 903, in _resolve_lookup
    raise VariableDoesNotExist(
django.template.base.VariableDoesNotExist: Failed lookup for key [partner1_progress] in {'partner1': 'developer2', 'partner2': 'developer', 'start_time': datetime.datetime(2025, 1, 5, 15, 52, 49, 883013, tzinfo=datetime.timezone.utc), 'end_time': datetime.datetime(2025, 1, 8, 15, 52, 49, 882451, tzinfo=datetime.timezone.utc), 'size': 250, 'progress_partner1': 0, 'progress_partner2': 0, 'is_open': True}
Exception while resolving variable 'partner2_progress' in template 'pomo/common_rooms.html'.
Traceback (most recent call last):
  File "/home/timoh/projects/master-o-meter/.venv/lib/python3.9/site-packages/django/template/base.py", line 880, in _resolve_lookup
    current = current[bit]
KeyError: 'partner2_progress'

During handling of the above exception, another exception occurred:

Traceback (most recent call last):
  File "/home/timoh/projects/master-o-meter/.venv/lib/python3.9/site-packages/django/template/base.py", line 890, in _resolve_lookup
    current = getattr(current, bit)
AttributeError: 'dict' object has no attribute 'partner2_progress'

During handling of the above exception, another exception occurred:

Traceback (most recent call last):
  File "/home/timoh/projects/master-o-meter/.venv/lib/python3.9/site-packages/django/template/base.py", line 896, in _resolve_lookup
    current = current[int(bit)]
ValueError: invalid literal for int() with base 10: 'partner2_progress'

During handling of the above exception, another exception occurred:

Traceback (most recent call last):
  File "/home/timoh/projects/master-o-meter/.venv/lib/python3.9/site-packages/django/template/base.py", line 903, in _resolve_lookup
    raise VariableDoesNotExist(
django.template.base.VariableDoesNotExist: Failed lookup for key [partner2_progress] in {'partner1': 'developer2', 'partner2': 'developer', 'start_time': datetime.datetime(2025, 1, 5, 15, 52, 49, 883013, tzinfo=datetime.timezone.utc), 'end_time': datetime.datetime(2025, 1, 8, 15, 52, 49, 882451, tzinfo=datetime.timezone.utc), 'size': 250, 'progress_partner1': 0, 'progress_partner2': 0, 'is_open': True}
Exception while resolving variable 'is_completed' in template 'pomo/common_rooms.html'.
Traceback (most recent call last):
  File "/home/timoh/projects/master-o-meter/.venv/lib/python3.9/site-packages/django/template/base.py", line 880, in _resolve_lookup
    current = current[bit]
KeyError: 'is_completed'

During handling of the above exception, another exception occurred:

Traceback (most recent call last):
  File "/home/timoh/projects/master-o-meter/.venv/lib/python3.9/site-packages/django/template/base.py", line 890, in _resolve_lookup
    current = getattr(current, bit)
AttributeError: 'dict' object has no attribute 'is_completed'

During handling of the above exception, another exception occurred:

Traceback (most recent call last):
  File "/home/timoh/projects/master-o-meter/.venv/lib/python3.9/site-packages/django/template/base.py", line 896, in _resolve_lookup
    current = current[int(bit)]
ValueError: invalid literal for int() with base 10: 'is_completed'

During handling of the above exception, another exception occurred:

Traceback (most recent call last):
  File "/home/timoh/projects/master-o-meter/.venv/lib/python3.9/site-packages/django/template/base.py", line 903, in _resolve_lookup
    raise VariableDoesNotExist(
django.template.base.VariableDoesNotExist: Failed lookup for key [is_completed] in {'partner1': 'developer2', 'partner2': 'developer', 'start_time': datetime.datetime(2025, 1, 5, 15, 52, 49, 883013, tzinfo=datetime.timezone.utc), 'end_time': datetime.datetime(2025, 1, 8, 15, 52, 49, 882451, tzinfo=datetime.timezone.utc), 'size': 250, 'progress_partner1': 0, 'progress_partner2': 0, 'is_open': True}
Not Found: /favicon.ico
Exception while resolving variable 'partner1_progress' in template 'pomo/common_rooms.html'.
Traceback (most recent call last):
  File "/home/timoh/projects/master-o-meter/.venv/lib/python3.9/site-packages/django/template/base.py", line 880, in _resolve_lookup
    current = current[bit]
KeyError: 'partner1_progress'

During handling of the above exception, another exception occurred:

Traceback (most recent call last):
  File "/home/timoh/projects/master-o-meter/.venv/lib/python3.9/site-packages/django/template/base.py", line 890, in _resolve_lookup
    current = getattr(current, bit)
AttributeError: 'dict' object has no attribute 'partner1_progress'

During handling of the above exception, another exception occurred:

Traceback (most recent call last):
  File "/home/timoh/projects/master-o-meter/.venv/lib/python3.9/site-packages/django/template/base.py", line 896, in _resolve_lookup
    current = current[int(bit)]
ValueError: invalid literal for int() with base 10: 'partner1_progress'

During handling of the above exception, another exception occurred:

Traceback (most recent call last):
  File "/home/timoh/projects/master-o-meter/.venv/lib/python3.9/site-packages/django/template/base.py", line 903, in _resolve_lookup
    raise VariableDoesNotExist(
django.template.base.VariableDoesNotExist: Failed lookup for key [partner1_progress] in {'partner1': 'developer2', 'partner2': 'developer', 'start_time': datetime.datetime(2025, 1, 5, 15, 52, 49, 883013, tzinfo=datetime.timezone.utc), 'end_time': datetime.datetime(2025, 1, 8, 15, 52, 49, 882451, tzinfo=datetime.timezone.utc), 'size': 250, 'progress_partner1': 0, 'progress_partner2': 0, 'is_open': True}
Exception while resolving variable 'partner2_progress' in template 'pomo/common_rooms.html'.
Traceback (most recent call last):
  File "/home/timoh/projects/master-o-meter/.venv/lib/python3.9/site-packages/django/template/base.py", line 880, in _resolve_lookup
    current = current[bit]
KeyError: 'partner2_progress'

During handling of the above exception, another exception occurred:

Traceback (most recent call last):
  File "/home/timoh/projects/master-o-meter/.venv/lib/python3.9/site-packages/django/template/base.py", line 890, in _resolve_lookup
    current = getattr(current, bit)
AttributeError: 'dict' object has no attribute 'partner2_progress'

During handling of the above exception, another exception occurred:

Traceback (most recent call last):
  File "/home/timoh/projects/master-o-meter/.venv/lib/python3.9/site-packages/django/template/base.py", line 896, in _resolve_lookup
    current = current[int(bit)]
ValueError: invalid literal for int() with base 10: 'partner2_progress'

During handling of the above exception, another exception occurred:

Traceback (most recent call last):
  File "/home/timoh/projects/master-o-meter/.venv/lib/python3.9/site-packages/django/template/base.py", line 903, in _resolve_lookup
    raise VariableDoesNotExist(
django.template.base.VariableDoesNotExist: Failed lookup for key [partner2_progress] in {'partner1': 'developer2', 'partner2': 'developer', 'start_time': datetime.datetime(2025, 1, 5, 15, 52, 49, 883013, tzinfo=datetime.timezone.utc), 'end_time': datetime.datetime(2025, 1, 8, 15, 52, 49, 882451, tzinfo=datetime.timezone.utc), 'size': 250, 'progress_partner1': 0, 'progress_partner2': 0, 'is_open': True}
Exception while resolving variable 'is_completed' in template 'pomo/common_rooms.html'.
Traceback (most recent call last):
  File "/home/timoh/projects/master-o-meter/.venv/lib/python3.9/site-packages/django/template/base.py", line 880, in _resolve_lookup
    current = current[bit]
KeyError: 'is_completed'

During handling of the above exception, another exception occurred:

Traceback (most recent call last):
  File "/home/timoh/projects/master-o-meter/.venv/lib/python3.9/site-packages/django/template/base.py", line 890, in _resolve_lookup
    current = getattr(current, bit)
AttributeError: 'dict' object has no attribute 'is_completed'

During handling of the above exception, another exception occurred:

Traceback (most recent call last):
  File "/home/timoh/projects/master-o-meter/.venv/lib/python3.9/site-packages/django/template/base.py", line 896, in _resolve_lookup
    current = current[int(bit)]
ValueError: invalid literal for int() with base 10: 'is_completed'

During handling of the above exception, another exception occurred:

Traceback (most recent call last):
  File "/home/timoh/projects/master-o-meter/.venv/lib/python3.9/site-packages/django/template/base.py", line 903, in _resolve_lookup
    raise VariableDoesNotExist(
django.template.base.VariableDoesNotExist: Failed lookup for key [is_completed] in {'partner1': 'developer2', 'partner2': 'developer', 'start_time': datetime.datetime(2025, 1, 5, 15, 52, 49, 883013, tzinfo=datetime.timezone.utc), 'end_time': datetime.datetime(2025, 1, 8, 15, 52, 49, 882451, tzinfo=datetime.timezone.utc), 'size': 250, 'progress_partner1': 0, 'progress_partner2': 0, 'is_open': True}
Exception while resolving variable 'partner1_progress' in template 'pomo/common_rooms.html'.
Traceback (most recent call last):
  File "/home/timoh/projects/master-o-meter/.venv/lib/python3.9/site-packages/django/template/base.py", line 880, in _resolve_lookup
    current = current[bit]
KeyError: 'partner1_progress'

During handling of the above exception, another exception occurred:

Traceback (most recent call last):
  File "/home/timoh/projects/master-o-meter/.venv/lib/python3.9/site-packages/django/template/base.py", line 890, in _resolve_lookup
    current = getattr(current, bit)
AttributeError: 'dict' object has no attribute 'partner1_progress'

During handling of the above exception, another exception occurred:

Traceback (most recent call last):
  File "/home/timoh/projects/master-o-meter/.venv/lib/python3.9/site-packages/django/template/base.py", line 896, in _resolve_lookup
    current = current[int(bit)]
ValueError: invalid literal for int() with base 10: 'partner1_progress'

During handling of the above exception, another exception occurred:

Traceback (most recent call last):
  File "/home/timoh/projects/master-o-meter/.venv/lib/python3.9/site-packages/django/template/base.py", line 903, in _resolve_lookup
    raise VariableDoesNotExist(
django.template.base.VariableDoesNotExist: Failed lookup for key [partner1_progress] in {'partner1': 'developer2', 'partner2': 'developer', 'start_time': datetime.datetime(2025, 1, 5, 15, 52, 49, 883013, tzinfo=datetime.timezone.utc), 'end_time': datetime.datetime(2025, 1, 8, 15, 52, 49, 882451, tzinfo=datetime.timezone.utc), 'size': 250, 'progress_partner1': 0, 'progress_partner2': 0, 'is_open': True}
Exception while resolving variable 'partner2_progress' in template 'pomo/common_rooms.html'.
Traceback (most recent call last):
  File "/home/timoh/projects/master-o-meter/.venv/lib/python3.9/site-packages/django/template/base.py", line 880, in _resolve_lookup
    current = current[bit]
KeyError: 'partner2_progress'

During handling of the above exception, another exception occurred:

Traceback (most recent call last):
  File "/home/timoh/projects/master-o-meter/.venv/lib/python3.9/site-packages/django/template/base.py", line 890, in _resolve_lookup
    current = getattr(current, bit)
AttributeError: 'dict' object has no attribute 'partner2_progress'

During handling of the above exception, another exception occurred:

Traceback (most recent call last):
  File "/home/timoh/projects/master-o-meter/.venv/lib/python3.9/site-packages/django/template/base.py", line 896, in _resolve_lookup
    current = current[int(bit)]
ValueError: invalid literal for int() with base 10: 'partner2_progress'

During handling of the above exception, another exception occurred:

Traceback (most recent call last):
  File "/home/timoh/projects/master-o-meter/.venv/lib/python3.9/site-packages/django/template/base.py", line 903, in _resolve_lookup
    raise VariableDoesNotExist(
django.template.base.VariableDoesNotExist: Failed lookup for key [partner2_progress] in {'partner1': 'developer2', 'partner2': 'developer', 'start_time': datetime.datetime(2025, 1, 5, 15, 52, 49, 883013, tzinfo=datetime.timezone.utc), 'end_time': datetime.datetime(2025, 1, 8, 15, 52, 49, 882451, tzinfo=datetime.timezone.utc), 'size': 250, 'progress_partner1': 0, 'progress_partner2': 0, 'is_open': True}
Exception while resolving variable 'is_completed' in template 'pomo/common_rooms.html'.
Traceback (most recent call last):
  File "/home/timoh/projects/master-o-meter/.venv/lib/python3.9/site-packages/django/template/base.py", line 880, in _resolve_lookup
    current = current[bit]
KeyError: 'is_completed'

During handling of the above exception, another exception occurred:

Traceback (most recent call last):
  File "/home/timoh/projects/master-o-meter/.venv/lib/python3.9/site-packages/django/template/base.py", line 890, in _resolve_lookup
    current = getattr(current, bit)
AttributeError: 'dict' object has no attribute 'is_completed'

During handling of the above exception, another exception occurred:

Traceback (most recent call last):
  File "/home/timoh/projects/master-o-meter/.venv/lib/python3.9/site-packages/django/template/base.py", line 896, in _resolve_lookup
    current = current[int(bit)]
ValueError: invalid literal for int() with base 10: 'is_completed'

During handling of the above exception, another exception occurred:

Traceback (most recent call last):
  File "/home/timoh/projects/master-o-meter/.venv/lib/python3.9/site-packages/django/template/base.py", line 903, in _resolve_lookup
    raise VariableDoesNotExist(
django.template.base.VariableDoesNotExist: Failed lookup for key [is_completed] in {'partner1': 'developer2', 'partner2': 'developer', 'start_time': datetime.datetime(2025, 1, 5, 15, 52, 49, 883013, tzinfo=datetime.timezone.utc), 'end_time': datetime.datetime(2025, 1, 8, 15, 52, 49, 882451, tzinfo=datetime.timezone.utc), 'size': 250, 'progress_partner1': 0, 'progress_partner2': 0, 'is_open': True}
Exception while resolving variable 'player_state_json' in template 'pomo/map.html'.
Traceback (most recent call last):
  File "/home/timoh/projects/master-o-meter/.venv/lib/python3.9/site-packages/django/template/base.py", line 880, in _resolve_lookup
    current = current[bit]
  File "/home/timoh/projects/master-o-meter/.venv/lib/python3.9/site-packages/django/template/context.py", line 83, in __getitem__
    raise KeyError(key)
KeyError: 'player_state_json'

During handling of the above exception, another exception occurred:

Traceback (most recent call last):
  File "/home/timoh/projects/master-o-meter/.venv/lib/python3.9/site-packages/django/template/base.py", line 886, in _resolve_lookup
    if isinstance(current, BaseContext) and getattr(
AttributeError: type object 'RequestContext' has no attribute 'player_state_json'

During handling of the above exception, another exception occurred:

Traceback (most recent call last):
  File "/home/timoh/projects/master-o-meter/.venv/lib/python3.9/site-packages/django/template/base.py", line 896, in _resolve_lookup
    current = current[int(bit)]
ValueError: invalid literal for int() with base 10: 'player_state_json'

During handling of the above exception, another exception occurred:

Traceback (most recent call last):
  File "/home/timoh/projects/master-o-meter/.venv/lib/python3.9/site-packages/django/template/base.py", line 903, in _resolve_lookup
    raise VariableDoesNotExist(
django.template.base.VariableDoesNotExist: Failed lookup for key [player_state_json] in [{'True': True, 'False': False, 'None': None}, {'csrf_token': <SimpleLazyObject: 'zFsKUA2LnxXLMZ2hEB4LhMEHERvkeklgHCq336uZOqG4XaxrWjtl8V3uSO97dUKY'>, 'request': <WSGIRequest: GET '/pomo/'>, 'user': <SimpleLazyObject: <User: developer2>>, 'perms': PermWrapper(<SimpleLazyObject: <User: developer2>>), 'messages': <FallbackStorage: request=<WSGIRequest: GET '/pomo/'>>, 'DEFAULT_MESSAGE_LEVELS': {'DEBUG': 10, 'INFO': 20, 'SUCCESS': 25, 'WARNING': 30, 'ERROR': 40}}, {}, {'total_pomos_alltime': 0, 'total_pomodoros_today': 0, 'streak': 0, 'is_developer': False, 'username': 'developer2'}]
Exception while resolving variable 'location_states_json' in template 'pomo/map.html'.
Traceback (most recent call last):
  File "/home/timoh/projects/master-o-meter/.venv/lib/python3.9/site-packages/django/template/base.py", line 880, in _resolve_lookup
    current = current[bit]
  File "/home/timoh/projects/master-o-meter/.venv/lib/python3.9/site-packages/django/template/context.py", line 83, in __getitem__
    raise KeyError(key)
KeyError: 'location_states_json'

During handling of the above exception, another exception occurred:

Traceback (most recent call last):
  File "/home/timoh/projects/master-o-meter/.venv/lib/python3.9/site-packages/django/template/base.py", line 886, in _resolve_lookup
    if isinstance(current, BaseContext) and getattr(
AttributeError: type object 'RequestContext' has no attribute 'location_states_json'

During handling of the above exception, another exception occurred:

Traceback (most recent call last):
  File "/home/timoh/projects/master-o-meter/.venv/lib/python3.9/site-packages/django/template/base.py", line 896, in _resolve_lookup
    current = current[int(bit)]
ValueError: invalid literal for int() with base 10: 'location_states_json'

During handling of the above exception, another exception occurred:

Traceback (most recent call last):
  File "/home/timoh/projects/master-o-meter/.venv/lib/python3.9/site-packages/django/template/base.py", line 903, in _resolve_lookup
    raise VariableDoesNotExist(
django.template.base.VariableDoesNotExist: Failed lookup for key [location_states_json] in [{'True': True, 'False': False, 'None': None}, {'csrf_token': <SimpleLazyObject: 'zFsKUA2LnxXLMZ2hEB4LhMEHERvkeklgHCq336uZOqG4XaxrWjtl8V3uSO97dUKY'>, 'request': <WSGIRequest: GET '/pomo/'>, 'user': <SimpleLazyObject: <User: developer2>>, 'perms': PermWrapper(<SimpleLazyObject: <User: developer2>>), 'messages': <FallbackStorage: request=<WSGIRequest: GET '/pomo/'>>, 'DEFAULT_MESSAGE_LEVELS': {'DEBUG': 10, 'INFO': 20, 'SUCCESS': 25, 'WARNING': 30, 'ERROR': 40}}, {}, {'total_pomos_alltime': 0, 'total_pomodoros_today': 0, 'streak': 0, 'is_developer': False, 'username': 'developer2'}]
Exception while resolving variable 'partner1_progress' in template 'pomo/common_rooms.html'.
Traceback (most recent call last):
  File "/home/timoh/projects/master-o-meter/.venv/lib/python3.9/site-packages/django/template/base.py", line 880, in _resolve_lookup
    current = current[bit]
KeyError: 'partner1_progress'

During handling of the above exception, another exception occurred:

Traceback (most recent call last):
  File "/home/timoh/projects/master-o-meter/.venv/lib/python3.9/site-packages/django/template/base.py", line 890, in _resolve_lookup
    current = getattr(current, bit)
AttributeError: 'dict' object has no attribute 'partner1_progress'

During handling of the above exception, another exception occurred:

Traceback (most recent call last):
  File "/home/timoh/projects/master-o-meter/.venv/lib/python3.9/site-packages/django/template/base.py", line 896, in _resolve_lookup
    current = current[int(bit)]
ValueError: invalid literal for int() with base 10: 'partner1_progress'

During handling of the above exception, another exception occurred:

Traceback (most recent call last):
  File "/home/timoh/projects/master-o-meter/.venv/lib/python3.9/site-packages/django/template/base.py", line 903, in _resolve_lookup
    raise VariableDoesNotExist(
django.template.base.VariableDoesNotExist: Failed lookup for key [partner1_progress] in {'partner1': 'developer2', 'partner2': 'developer', 'start_time': datetime.datetime(2025, 1, 5, 15, 52, 49, 883013, tzinfo=datetime.timezone.utc), 'end_time': datetime.datetime(2025, 1, 8, 15, 52, 49, 882451, tzinfo=datetime.timezone.utc), 'size': 250, 'progress_partner1': 0, 'progress_partner2': 0, 'is_open': True}
Exception while resolving variable 'partner2_progress' in template 'pomo/common_rooms.html'.
Traceback (most recent call last):
  File "/home/timoh/projects/master-o-meter/.venv/lib/python3.9/site-packages/django/template/base.py", line 880, in _resolve_lookup
    current = current[bit]
KeyError: 'partner2_progress'

During handling of the above exception, another exception occurred:

Traceback (most recent call last):
  File "/home/timoh/projects/master-o-meter/.venv/lib/python3.9/site-packages/django/template/base.py", line 890, in _resolve_lookup
    current = getattr(current, bit)
AttributeError: 'dict' object has no attribute 'partner2_progress'

During handling of the above exception, another exception occurred:

Traceback (most recent call last):
  File "/home/timoh/projects/master-o-meter/.venv/lib/python3.9/site-packages/django/template/base.py", line 896, in _resolve_lookup
    current = current[int(bit)]
ValueError: invalid literal for int() with base 10: 'partner2_progress'

During handling of the above exception, another exception occurred:

Traceback (most recent call last):
  File "/home/timoh/projects/master-o-meter/.venv/lib/python3.9/site-packages/django/template/base.py", line 903, in _resolve_lookup
    raise VariableDoesNotExist(
django.template.base.VariableDoesNotExist: Failed lookup for key [partner2_progress] in {'partner1': 'developer2', 'partner2': 'developer', 'start_time': datetime.datetime(2025, 1, 5, 15, 52, 49, 883013, tzinfo=datetime.timezone.utc), 'end_time': datetime.datetime(2025, 1, 8, 15, 52, 49, 882451, tzinfo=datetime.timezone.utc), 'size': 250, 'progress_partner1': 0, 'progress_partner2': 0, 'is_open': True}
Exception while resolving variable 'is_completed' in template 'pomo/common_rooms.html'.
Traceback (most recent call last):
  File "/home/timoh/projects/master-o-meter/.venv/lib/python3.9/site-packages/django/template/base.py", line 880, in _resolve_lookup
    current = current[bit]
KeyError: 'is_completed'

During handling of the above exception, another exception occurred:

Traceback (most recent call last):
  File "/home/timoh/projects/master-o-meter/.venv/lib/python3.9/site-packages/django/template/base.py", line 890, in _resolve_lookup
    current = getattr(current, bit)
AttributeError: 'dict' object has no attribute 'is_completed'

During handling of the above exception, another exception occurred:

Traceback (most recent call last):
  File "/home/timoh/projects/master-o-meter/.venv/lib/python3.9/site-packages/django/template/base.py", line 896, in _resolve_lookup
    current = current[int(bit)]
ValueError: invalid literal for int() with base 10: 'is_completed'

During handling of the above exception, another exception occurred:

Traceback (most recent call last):
  File "/home/timoh/projects/master-o-meter/.venv/lib/python3.9/site-packages/django/template/base.py", line 903, in _resolve_lookup
    raise VariableDoesNotExist(
django.template.base.VariableDoesNotExist: Failed lookup for key [is_completed] in {'partner1': 'developer2', 'partner2': 'developer', 'start_time': datetime.datetime(2025, 1, 5, 15, 52, 49, 883013, tzinfo=datetime.timezone.utc), 'end_time': datetime.datetime(2025, 1, 8, 15, 52, 49, 882451, tzinfo=datetime.timezone.utc), 'size': 250, 'progress_partner1': 0, 'progress_partner2': 0, 'is_open': True}
Exception while resolving variable 'partner1_progress' in template 'pomo/common_rooms.html'.
Traceback (most recent call last):
  File "/home/timoh/projects/master-o-meter/.venv/lib/python3.9/site-packages/django/template/base.py", line 880, in _resolve_lookup
    current = current[bit]
KeyError: 'partner1_progress'

During handling of the above exception, another exception occurred:

Traceback (most recent call last):
  File "/home/timoh/projects/master-o-meter/.venv/lib/python3.9/site-packages/django/template/base.py", line 890, in _resolve_lookup
    current = getattr(current, bit)
AttributeError: 'dict' object has no attribute 'partner1_progress'

During handling of the above exception, another exception occurred:

Traceback (most recent call last):
  File "/home/timoh/projects/master-o-meter/.venv/lib/python3.9/site-packages/django/template/base.py", line 896, in _resolve_lookup
    current = current[int(bit)]
ValueError: invalid literal for int() with base 10: 'partner1_progress'

During handling of the above exception, another exception occurred:

Traceback (most recent call last):
  File "/home/timoh/projects/master-o-meter/.venv/lib/python3.9/site-packages/django/template/base.py", line 903, in _resolve_lookup
    raise VariableDoesNotExist(
django.template.base.VariableDoesNotExist: Failed lookup for key [partner1_progress] in {'partner1': 'developer2', 'partner2': 'developer', 'start_time': datetime.datetime(2025, 1, 5, 15, 52, 49, 883013, tzinfo=datetime.timezone.utc), 'end_time': datetime.datetime(2025, 1, 8, 15, 52, 49, 882451, tzinfo=datetime.timezone.utc), 'size': 250, 'progress_partner1': 0, 'progress_partner2': 0, 'is_open': True}
Exception while resolving variable 'partner2_progress' in template 'pomo/common_rooms.html'.
Traceback (most recent call last):
  File "/home/timoh/projects/master-o-meter/.venv/lib/python3.9/site-packages/django/template/base.py", line 880, in _resolve_lookup
    current = current[bit]
KeyError: 'partner2_progress'

During handling of the above exception, another exception occurred:

Traceback (most recent call last):
  File "/home/timoh/projects/master-o-meter/.venv/lib/python3.9/site-packages/django/template/base.py", line 890, in _resolve_lookup
    current = getattr(current, bit)
AttributeError: 'dict' object has no attribute 'partner2_progress'

During handling of the above exception, another exception occurred:

Traceback (most recent call last):
  File "/home/timoh/projects/master-o-meter/.venv/lib/python3.9/site-packages/django/template/base.py", line 896, in _resolve_lookup
    current = current[int(bit)]
ValueError: invalid literal for int() with base 10: 'partner2_progress'

During handling of the above exception, another exception occurred:

Traceback (most recent call last):
  File "/home/timoh/projects/master-o-meter/.venv/lib/python3.9/site-packages/django/template/base.py", line 903, in _resolve_lookup
    raise VariableDoesNotExist(
django.template.base.VariableDoesNotExist: Failed lookup for key [partner2_progress] in {'partner1': 'developer2', 'partner2': 'developer', 'start_time': datetime.datetime(2025, 1, 5, 15, 52, 49, 883013, tzinfo=datetime.timezone.utc), 'end_time': datetime.datetime(2025, 1, 8, 15, 52, 49, 882451, tzinfo=datetime.timezone.utc), 'size': 250, 'progress_partner1': 0, 'progress_partner2': 0, 'is_open': True}
Exception while resolving variable 'is_completed' in template 'pomo/common_rooms.html'.
Traceback (most recent call last):
  File "/home/timoh/projects/master-o-meter/.venv/lib/python3.9/site-packages/django/template/base.py", line 880, in _resolve_lookup
    current = current[bit]
KeyError: 'is_completed'

During handling of the above exception, another exception occurred:

Traceback (most recent call last):
  File "/home/timoh/projects/master-o-meter/.venv/lib/python3.9/site-packages/django/template/base.py", line 890, in _resolve_lookup
    current = getattr(current, bit)
AttributeError: 'dict' object has no attribute 'is_completed'

During handling of the above exception, another exception occurred:

Traceback (most recent call last):
  File "/home/timoh/projects/master-o-meter/.venv/lib/python3.9/site-packages/django/template/base.py", line 896, in _resolve_lookup
    current = current[int(bit)]
ValueError: invalid literal for int() with base 10: 'is_completed'

During handling of the above exception, another exception occurred:

Traceback (most recent call last):
  File "/home/timoh/projects/master-o-meter/.venv/lib/python3.9/site-packages/django/template/base.py", line 903, in _resolve_lookup
    raise VariableDoesNotExist(
django.template.base.VariableDoesNotExist: Failed lookup for key [is_completed] in {'partner1': 'developer2', 'partner2': 'developer', 'start_time': datetime.datetime(2025, 1, 5, 15, 52, 49, 883013, tzinfo=datetime.timezone.utc), 'end_time': datetime.datetime(2025, 1, 8, 15, 52, 49, 882451, tzinfo=datetime.timezone.utc), 'size': 250, 'progress_partner1': 0, 'progress_partner2': 0, 'is_open': True}
Exception while resolving variable 'partner1_progress' in template 'pomo/common_rooms.html'.
Traceback (most recent call last):
  File "/home/timoh/projects/master-o-meter/.venv/lib/python3.9/site-packages/django/template/base.py", line 880, in _resolve_lookup
    current = current[bit]
KeyError: 'partner1_progress'

During handling of the above exception, another exception occurred:

Traceback (most recent call last):
  File "/home/timoh/projects/master-o-meter/.venv/lib/python3.9/site-packages/django/template/base.py", line 890, in _resolve_lookup
    current = getattr(current, bit)
AttributeError: 'dict' object has no attribute 'partner1_progress'

During handling of the above exception, another exception occurred:

Traceback (most recent call last):
  File "/home/timoh/projects/master-o-meter/.venv/lib/python3.9/site-packages/django/template/base.py", line 896, in _resolve_lookup
    current = current[int(bit)]
ValueError: invalid literal for int() with base 10: 'partner1_progress'

During handling of the above exception, another exception occurred:

Traceback (most recent call last):
  File "/home/timoh/projects/master-o-meter/.venv/lib/python3.9/site-packages/django/template/base.py", line 903, in _resolve_lookup
    raise VariableDoesNotExist(
django.template.base.VariableDoesNotExist: Failed lookup for key [partner1_progress] in {'partner1': 'developer2', 'partner2': 'developer', 'start_time': datetime.datetime(2025, 1, 5, 15, 52, 49, 883013, tzinfo=datetime.timezone.utc), 'end_time': datetime.datetime(2025, 1, 8, 15, 52, 49, 882451, tzinfo=datetime.timezone.utc), 'size': 250, 'progress_partner1': 0, 'progress_partner2': 0, 'is_open': True}
Exception while resolving variable 'partner2_progress' in template 'pomo/common_rooms.html'.
Traceback (most recent call last):
  File "/home/timoh/projects/master-o-meter/.venv/lib/python3.9/site-packages/django/template/base.py", line 880, in _resolve_lookup
    current = current[bit]
KeyError: 'partner2_progress'

During handling of the above exception, another exception occurred:

Traceback (most recent call last):
  File "/home/timoh/projects/master-o-meter/.venv/lib/python3.9/site-packages/django/template/base.py", line 890, in _resolve_lookup
    current = getattr(current, bit)
AttributeError: 'dict' object has no attribute 'partner2_progress'

During handling of the above exception, another exception occurred:

Traceback (most recent call last):
  File "/home/timoh/projects/master-o-meter/.venv/lib/python3.9/site-packages/django/template/base.py", line 896, in _resolve_lookup
    current = current[int(bit)]
ValueError: invalid literal for int() with base 10: 'partner2_progress'

During handling of the above exception, another exception occurred:

Traceback (most recent call last):
  File "/home/timoh/projects/master-o-meter/.venv/lib/python3.9/site-packages/django/template/base.py", line 903, in _resolve_lookup
    raise VariableDoesNotExist(
django.template.base.VariableDoesNotExist: Failed lookup for key [partner2_progress] in {'partner1': 'developer2', 'partner2': 'developer', 'start_time': datetime.datetime(2025, 1, 5, 15, 52, 49, 883013, tzinfo=datetime.timezone.utc), 'end_time': datetime.datetime(2025, 1, 8, 15, 52, 49, 882451, tzinfo=datetime.timezone.utc), 'size': 250, 'progress_partner1': 0, 'progress_partner2': 0, 'is_open': True}
Exception while resolving variable 'is_completed' in template 'pomo/common_rooms.html'.
Traceback (most recent call last):
  File "/home/timoh/projects/master-o-meter/.venv/lib/python3.9/site-packages/django/template/base.py", line 880, in _resolve_lookup
    current = current[bit]
KeyError: 'is_completed'

During handling of the above exception, another exception occurred:

Traceback (most recent call last):
  File "/home/timoh/projects/master-o-meter/.venv/lib/python3.9/site-packages/django/template/base.py", line 890, in _resolve_lookup
    current = getattr(current, bit)
AttributeError: 'dict' object has no attribute 'is_completed'

During handling of the above exception, another exception occurred:

Traceback (most recent call last):
  File "/home/timoh/projects/master-o-meter/.venv/lib/python3.9/site-packages/django/template/base.py", line 896, in _resolve_lookup
    current = current[int(bit)]
ValueError: invalid literal for int() with base 10: 'is_completed'

During handling of the above exception, another exception occurred:

Traceback (most recent call last):
  File "/home/timoh/projects/master-o-meter/.venv/lib/python3.9/site-packages/django/template/base.py", line 903, in _resolve_lookup
    raise VariableDoesNotExist(
django.template.base.VariableDoesNotExist: Failed lookup for key [is_completed] in {'partner1': 'developer2', 'partner2': 'developer', 'start_time': datetime.datetime(2025, 1, 5, 15, 52, 49, 883013, tzinfo=datetime.timezone.utc), 'end_time': datetime.datetime(2025, 1, 8, 15, 52, 49, 882451, tzinfo=datetime.timezone.utc), 'size': 250, 'progress_partner1': 0, 'progress_partner2': 0, 'is_open': True}
Exception while resolving variable 'player_state_json' in template 'pomo/map.html'.
Traceback (most recent call last):
  File "/home/timoh/projects/master-o-meter/.venv/lib/python3.9/site-packages/django/template/base.py", line 880, in _resolve_lookup
    current = current[bit]
  File "/home/timoh/projects/master-o-meter/.venv/lib/python3.9/site-packages/django/template/context.py", line 83, in __getitem__
    raise KeyError(key)
KeyError: 'player_state_json'

During handling of the above exception, another exception occurred:

Traceback (most recent call last):
  File "/home/timoh/projects/master-o-meter/.venv/lib/python3.9/site-packages/django/template/base.py", line 886, in _resolve_lookup
    if isinstance(current, BaseContext) and getattr(
AttributeError: type object 'RequestContext' has no attribute 'player_state_json'

During handling of the above exception, another exception occurred:

Traceback (most recent call last):
  File "/home/timoh/projects/master-o-meter/.venv/lib/python3.9/site-packages/django/template/base.py", line 896, in _resolve_lookup
    current = current[int(bit)]
ValueError: invalid literal for int() with base 10: 'player_state_json'

During handling of the above exception, another exception occurred:

Traceback (most recent call last):
  File "/home/timoh/projects/master-o-meter/.venv/lib/python3.9/site-packages/django/template/base.py", line 903, in _resolve_lookup
    raise VariableDoesNotExist(
django.template.base.VariableDoesNotExist: Failed lookup for key [player_state_json] in [{'True': True, 'False': False, 'None': None}, {'csrf_token': <SimpleLazyObject: 'J2svobTiu8kZ8ajntbNEOWpI7WtQDofMjy50cCoBj4Vs3WHubVIVZmzeReHs0hv8'>, 'request': <WSGIRequest: GET '/pomo/'>, 'user': <SimpleLazyObject: <User: developer>>, 'perms': PermWrapper(<SimpleLazyObject: <User: developer>>), 'messages': <FallbackStorage: request=<WSGIRequest: GET '/pomo/'>>, 'DEFAULT_MESSAGE_LEVELS': {'DEBUG': 10, 'INFO': 20, 'SUCCESS': 25, 'WARNING': 30, 'ERROR': 40}}, {}, {'total_pomos_alltime': 25, 'total_pomodoros_today': 0, 'streak': 3, 'is_developer': True, 'username': 'developer'}]
Exception while resolving variable 'location_states_json' in template 'pomo/map.html'.
Traceback (most recent call last):
  File "/home/timoh/projects/master-o-meter/.venv/lib/python3.9/site-packages/django/template/base.py", line 880, in _resolve_lookup
    current = current[bit]
  File "/home/timoh/projects/master-o-meter/.venv/lib/python3.9/site-packages/django/template/context.py", line 83, in __getitem__
    raise KeyError(key)
KeyError: 'location_states_json'

During handling of the above exception, another exception occurred:

Traceback (most recent call last):
  File "/home/timoh/projects/master-o-meter/.venv/lib/python3.9/site-packages/django/template/base.py", line 886, in _resolve_lookup
    if isinstance(current, BaseContext) and getattr(
AttributeError: type object 'RequestContext' has no attribute 'location_states_json'

During handling of the above exception, another exception occurred:

Traceback (most recent call last):
  File "/home/timoh/projects/master-o-meter/.venv/lib/python3.9/site-packages/django/template/base.py", line 896, in _resolve_lookup
    current = current[int(bit)]
ValueError: invalid literal for int() with base 10: 'location_states_json'

During handling of the above exception, another exception occurred:

Traceback (most recent call last):
  File "/home/timoh/projects/master-o-meter/.venv/lib/python3.9/site-packages/django/template/base.py", line 903, in _resolve_lookup
    raise VariableDoesNotExist(
django.template.base.VariableDoesNotExist: Failed lookup for key [location_states_json] in [{'True': True, 'False': False, 'None': None}, {'csrf_token': <SimpleLazyObject: 'J2svobTiu8kZ8ajntbNEOWpI7WtQDofMjy50cCoBj4Vs3WHubVIVZmzeReHs0hv8'>, 'request': <WSGIRequest: GET '/pomo/'>, 'user': <SimpleLazyObject: <User: developer>>, 'perms': PermWrapper(<SimpleLazyObject: <User: developer>>), 'messages': <FallbackStorage: request=<WSGIRequest: GET '/pomo/'>>, 'DEFAULT_MESSAGE_LEVELS': {'DEBUG': 10, 'INFO': 20, 'SUCCESS': 25, 'WARNING': 30, 'ERROR': 40}}, {}, {'total_pomos_alltime': 25, 'total_pomodoros_today': 0, 'streak': 3, 'is_developer': True, 'username': 'developer'}]
Exception while resolving variable 'partner1_progress' in template 'pomo/common_rooms.html'.
Traceback (most recent call last):
  File "/home/timoh/projects/master-o-meter/.venv/lib/python3.9/site-packages/django/template/base.py", line 880, in _resolve_lookup
    current = current[bit]
KeyError: 'partner1_progress'

During handling of the above exception, another exception occurred:

Traceback (most recent call last):
  File "/home/timoh/projects/master-o-meter/.venv/lib/python3.9/site-packages/django/template/base.py", line 890, in _resolve_lookup
    current = getattr(current, bit)
AttributeError: 'dict' object has no attribute 'partner1_progress'

During handling of the above exception, another exception occurred:

Traceback (most recent call last):
  File "/home/timoh/projects/master-o-meter/.venv/lib/python3.9/site-packages/django/template/base.py", line 896, in _resolve_lookup
    current = current[int(bit)]
ValueError: invalid literal for int() with base 10: 'partner1_progress'

During handling of the above exception, another exception occurred:

Traceback (most recent call last):
  File "/home/timoh/projects/master-o-meter/.venv/lib/python3.9/site-packages/django/template/base.py", line 903, in _resolve_lookup
    raise VariableDoesNotExist(
django.template.base.VariableDoesNotExist: Failed lookup for key [partner1_progress] in {'partner1': 'developer2', 'partner2': 'developer', 'start_time': datetime.datetime(2025, 1, 5, 15, 52, 49, 883013, tzinfo=datetime.timezone.utc), 'end_time': datetime.datetime(2025, 1, 8, 15, 52, 49, 882451, tzinfo=datetime.timezone.utc), 'size': 250, 'progress_partner1': 0, 'progress_partner2': 0, 'is_open': True}
Exception while resolving variable 'partner2_progress' in template 'pomo/common_rooms.html'.
Traceback (most recent call last):
  File "/home/timoh/projects/master-o-meter/.venv/lib/python3.9/site-packages/django/template/base.py", line 880, in _resolve_lookup
    current = current[bit]
KeyError: 'partner2_progress'

During handling of the above exception, another exception occurred:

Traceback (most recent call last):
  File "/home/timoh/projects/master-o-meter/.venv/lib/python3.9/site-packages/django/template/base.py", line 890, in _resolve_lookup
    current = getattr(current, bit)
AttributeError: 'dict' object has no attribute 'partner2_progress'

During handling of the above exception, another exception occurred:

Traceback (most recent call last):
  File "/home/timoh/projects/master-o-meter/.venv/lib/python3.9/site-packages/django/template/base.py", line 896, in _resolve_lookup
    current = current[int(bit)]
ValueError: invalid literal for int() with base 10: 'partner2_progress'

During handling of the above exception, another exception occurred:

Traceback (most recent call last):
  File "/home/timoh/projects/master-o-meter/.venv/lib/python3.9/site-packages/django/template/base.py", line 903, in _resolve_lookup
    raise VariableDoesNotExist(
django.template.base.VariableDoesNotExist: Failed lookup for key [partner2_progress] in {'partner1': 'developer2', 'partner2': 'developer', 'start_time': datetime.datetime(2025, 1, 5, 15, 52, 49, 883013, tzinfo=datetime.timezone.utc), 'end_time': datetime.datetime(2025, 1, 8, 15, 52, 49, 882451, tzinfo=datetime.timezone.utc), 'size': 250, 'progress_partner1': 0, 'progress_partner2': 0, 'is_open': True}
Exception while resolving variable 'is_completed' in template 'pomo/common_rooms.html'.
Traceback (most recent call last):
  File "/home/timoh/projects/master-o-meter/.venv/lib/python3.9/site-packages/django/template/base.py", line 880, in _resolve_lookup
    current = current[bit]
KeyError: 'is_completed'

During handling of the above exception, another exception occurred:

Traceback (most recent call last):
  File "/home/timoh/projects/master-o-meter/.venv/lib/python3.9/site-packages/django/template/base.py", line 890, in _resolve_lookup
    current = getattr(current, bit)
AttributeError: 'dict' object has no attribute 'is_completed'

During handling of the above exception, another exception occurred:

Traceback (most recent call last):
  File "/home/timoh/projects/master-o-meter/.venv/lib/python3.9/site-packages/django/template/base.py", line 896, in _resolve_lookup
    current = current[int(bit)]
ValueError: invalid literal for int() with base 10: 'is_completed'

During handling of the above exception, another exception occurred:

Traceback (most recent call last):
  File "/home/timoh/projects/master-o-meter/.venv/lib/python3.9/site-packages/django/template/base.py", line 903, in _resolve_lookup
    raise VariableDoesNotExist(
django.template.base.VariableDoesNotExist: Failed lookup for key [is_completed] in {'partner1': 'developer2', 'partner2': 'developer', 'start_time': datetime.datetime(2025, 1, 5, 15, 52, 49, 883013, tzinfo=datetime.timezone.utc), 'end_time': datetime.datetime(2025, 1, 8, 15, 52, 49, 882451, tzinfo=datetime.timezone.utc), 'size': 250, 'progress_partner1': 0, 'progress_partner2': 0, 'is_open': True}
Exception while resolving variable 'partner1_progress' in template 'pomo/common_rooms.html'.
Traceback (most recent call last):
  File "/home/timoh/projects/master-o-meter/.venv/lib/python3.9/site-packages/django/template/base.py", line 880, in _resolve_lookup
    current = current[bit]
KeyError: 'partner1_progress'

During handling of the above exception, another exception occurred:

Traceback (most recent call last):
  File "/home/timoh/projects/master-o-meter/.venv/lib/python3.9/site-packages/django/template/base.py", line 890, in _resolve_lookup
    current = getattr(current, bit)
AttributeError: 'dict' object has no attribute 'partner1_progress'

During handling of the above exception, another exception occurred:

Traceback (most recent call last):
  File "/home/timoh/projects/master-o-meter/.venv/lib/python3.9/site-packages/django/template/base.py", line 896, in _resolve_lookup
    current = current[int(bit)]
ValueError: invalid literal for int() with base 10: 'partner1_progress'

During handling of the above exception, another exception occurred:

Traceback (most recent call last):
  File "/home/timoh/projects/master-o-meter/.venv/lib/python3.9/site-packages/django/template/base.py", line 903, in _resolve_lookup
    raise VariableDoesNotExist(
django.template.base.VariableDoesNotExist: Failed lookup for key [partner1_progress] in {'partner1': 'developer2', 'partner2': 'developer', 'start_time': datetime.datetime(2025, 1, 5, 15, 52, 49, 883013, tzinfo=datetime.timezone.utc), 'end_time': datetime.datetime(2025, 1, 8, 15, 52, 49, 882451, tzinfo=datetime.timezone.utc), 'size': 250, 'progress_partner1': 0, 'progress_partner2': 0, 'is_open': True}
Exception while resolving variable 'partner2_progress' in template 'pomo/common_rooms.html'.
Traceback (most recent call last):
  File "/home/timoh/projects/master-o-meter/.venv/lib/python3.9/site-packages/django/template/base.py", line 880, in _resolve_lookup
    current = current[bit]
KeyError: 'partner2_progress'

During handling of the above exception, another exception occurred:

Traceback (most recent call last):
  File "/home/timoh/projects/master-o-meter/.venv/lib/python3.9/site-packages/django/template/base.py", line 890, in _resolve_lookup
    current = getattr(current, bit)
AttributeError: 'dict' object has no attribute 'partner2_progress'

During handling of the above exception, another exception occurred:

Traceback (most recent call last):
  File "/home/timoh/projects/master-o-meter/.venv/lib/python3.9/site-packages/django/template/base.py", line 896, in _resolve_lookup
    current = current[int(bit)]
ValueError: invalid literal for int() with base 10: 'partner2_progress'

During handling of the above exception, another exception occurred:

Traceback (most recent call last):
  File "/home/timoh/projects/master-o-meter/.venv/lib/python3.9/site-packages/django/template/base.py", line 903, in _resolve_lookup
    raise VariableDoesNotExist(
django.template.base.VariableDoesNotExist: Failed lookup for key [partner2_progress] in {'partner1': 'developer2', 'partner2': 'developer', 'start_time': datetime.datetime(2025, 1, 5, 15, 52, 49, 883013, tzinfo=datetime.timezone.utc), 'end_time': datetime.datetime(2025, 1, 8, 15, 52, 49, 882451, tzinfo=datetime.timezone.utc), 'size': 250, 'progress_partner1': 0, 'progress_partner2': 0, 'is_open': True}
Exception while resolving variable 'is_completed' in template 'pomo/common_rooms.html'.
Traceback (most recent call last):
  File "/home/timoh/projects/master-o-meter/.venv/lib/python3.9/site-packages/django/template/base.py", line 880, in _resolve_lookup
    current = current[bit]
KeyError: 'is_completed'

During handling of the above exception, another exception occurred:

Traceback (most recent call last):
  File "/home/timoh/projects/master-o-meter/.venv/lib/python3.9/site-packages/django/template/base.py", line 890, in _resolve_lookup
    current = getattr(current, bit)
AttributeError: 'dict' object has no attribute 'is_completed'

During handling of the above exception, another exception occurred:

Traceback (most recent call last):
  File "/home/timoh/projects/master-o-meter/.venv/lib/python3.9/site-packages/django/template/base.py", line 896, in _resolve_lookup
    current = current[int(bit)]
ValueError: invalid literal for int() with base 10: 'is_completed'

During handling of the above exception, another exception occurred:

Traceback (most recent call last):
  File "/home/timoh/projects/master-o-meter/.venv/lib/python3.9/site-packages/django/template/base.py", line 903, in _resolve_lookup
    raise VariableDoesNotExist(
django.template.base.VariableDoesNotExist: Failed lookup for key [is_completed] in {'partner1': 'developer2', 'partner2': 'developer', 'start_time': datetime.datetime(2025, 1, 5, 15, 52, 49, 883013, tzinfo=datetime.timezone.utc), 'end_time': datetime.datetime(2025, 1, 8, 15, 52, 49, 882451, tzinfo=datetime.timezone.utc), 'size': 250, 'progress_partner1': 0, 'progress_partner2': 0, 'is_open': True}
Exception while resolving variable 'partner1_progress' in template 'pomo/common_rooms.html'.
Traceback (most recent call last):
  File "/home/timoh/projects/master-o-meter/.venv/lib/python3.9/site-packages/django/template/base.py", line 880, in _resolve_lookup
    current = current[bit]
KeyError: 'partner1_progress'

During handling of the above exception, another exception occurred:

Traceback (most recent call last):
  File "/home/timoh/projects/master-o-meter/.venv/lib/python3.9/site-packages/django/template/base.py", line 890, in _resolve_lookup
    current = getattr(current, bit)
AttributeError: 'dict' object has no attribute 'partner1_progress'

During handling of the above exception, another exception occurred:

Traceback (most recent call last):
  File "/home/timoh/projects/master-o-meter/.venv/lib/python3.9/site-packages/django/template/base.py", line 896, in _resolve_lookup
    current = current[int(bit)]
ValueError: invalid literal for int() with base 10: 'partner1_progress'

During handling of the above exception, another exception occurred:

Traceback (most recent call last):
  File "/home/timoh/projects/master-o-meter/.venv/lib/python3.9/site-packages/django/template/base.py", line 903, in _resolve_lookup
    raise VariableDoesNotExist(
django.template.base.VariableDoesNotExist: Failed lookup for key [partner1_progress] in {'partner1': 'developer2', 'partner2': 'developer', 'start_time': datetime.datetime(2025, 1, 5, 22, 19, 0, 957163, tzinfo=datetime.timezone.utc), 'end_time': datetime.datetime(2025, 1, 8, 22, 19, 0, 955832, tzinfo=datetime.timezone.utc), 'size': 250, 'progress_partner1': 0, 'progress_partner2': 0, 'is_open': True}
Exception while resolving variable 'partner2_progress' in template 'pomo/common_rooms.html'.
Traceback (most recent call last):
  File "/home/timoh/projects/master-o-meter/.venv/lib/python3.9/site-packages/django/template/base.py", line 880, in _resolve_lookup
    current = current[bit]
KeyError: 'partner2_progress'

During handling of the above exception, another exception occurred:

Traceback (most recent call last):
  File "/home/timoh/projects/master-o-meter/.venv/lib/python3.9/site-packages/django/template/base.py", line 890, in _resolve_lookup
    current = getattr(current, bit)
AttributeError: 'dict' object has no attribute 'partner2_progress'

During handling of the above exception, another exception occurred:

Traceback (most recent call last):
  File "/home/timoh/projects/master-o-meter/.venv/lib/python3.9/site-packages/django/template/base.py", line 896, in _resolve_lookup
    current = current[int(bit)]
ValueError: invalid literal for int() with base 10: 'partner2_progress'

During handling of the above exception, another exception occurred:

Traceback (most recent call last):
  File "/home/timoh/projects/master-o-meter/.venv/lib/python3.9/site-packages/django/template/base.py", line 903, in _resolve_lookup
    raise VariableDoesNotExist(
django.template.base.VariableDoesNotExist: Failed lookup for key [partner2_progress] in {'partner1': 'developer2', 'partner2': 'developer', 'start_time': datetime.datetime(2025, 1, 5, 22, 19, 0, 957163, tzinfo=datetime.timezone.utc), 'end_time': datetime.datetime(2025, 1, 8, 22, 19, 0, 955832, tzinfo=datetime.timezone.utc), 'size': 250, 'progress_partner1': 0, 'progress_partner2': 0, 'is_open': True}
Exception while resolving variable 'is_completed' in template 'pomo/common_rooms.html'.
Traceback (most recent call last):
  File "/home/timoh/projects/master-o-meter/.venv/lib/python3.9/site-packages/django/template/base.py", line 880, in _resolve_lookup
    current = current[bit]
KeyError: 'is_completed'

During handling of the above exception, another exception occurred:

Traceback (most recent call last):
  File "/home/timoh/projects/master-o-meter/.venv/lib/python3.9/site-packages/django/template/base.py", line 890, in _resolve_lookup
    current = getattr(current, bit)
AttributeError: 'dict' object has no attribute 'is_completed'

During handling of the above exception, another exception occurred:

Traceback (most recent call last):
  File "/home/timoh/projects/master-o-meter/.venv/lib/python3.9/site-packages/django/template/base.py", line 896, in _resolve_lookup
    current = current[int(bit)]
ValueError: invalid literal for int() with base 10: 'is_completed'

During handling of the above exception, another exception occurred:

Traceback (most recent call last):
  File "/home/timoh/projects/master-o-meter/.venv/lib/python3.9/site-packages/django/template/base.py", line 903, in _resolve_lookup
    raise VariableDoesNotExist(
django.template.base.VariableDoesNotExist: Failed lookup for key [is_completed] in {'partner1': 'developer2', 'partner2': 'developer', 'start_time': datetime.datetime(2025, 1, 5, 22, 19, 0, 957163, tzinfo=datetime.timezone.utc), 'end_time': datetime.datetime(2025, 1, 8, 22, 19, 0, 955832, tzinfo=datetime.timezone.utc), 'size': 250, 'progress_partner1': 0, 'progress_partner2': 0, 'is_open': True}
